Workbook

Sheet Perfume
D1: =SUM(D5:D21) -> 0 | F1: =SUM(F5:F21) -> 0 | H1: =SUM(H5:H21) -> 0 | J1: =SUM(J5:J21) -> 0 | L1: =SUM(L5:L21) -> 0 | N1: =SUM(N5:N21) -> 0 | P1: =SUM(P5:P21) -> 0 | R1: =SUM(R5:R21) -> 0 | T1: =SUM(T5:T21) -> 0 | V1: =SUM(V5:V21) -> 0 | X1: =SUM(X5:X21) -> 0 | Z1: =SUM(Z5:Z21) -> 0 | AB1: =SUM(AB5:AB21) -> 0 | AD1: =SUM(AD5:AD21) -> 0 | AF1: =SUM(AF5:AF21) -> 1065 | AH1: =SUM(AH5:AH21) -> 383 | AJ1: =SUM(AJ5:AJ21) -> 436 | AL1: =SUM(AL5:AL21) -> 436 | AN1: =SUM(AN5:AN21) -> 0 | AP1: =SUM(AP5:AP21) -> 0 | AR1: =SUM(AR5:AR21) -> 0 | AT1: =SUM(AT5:AT21) -> 0 | AV1: =SUM(AV5:AV21) -> 0 | AX1: =SUM(AX5:AX21) -> 0 | AZ1: =SUM(AZ5:AZ21) -> 0 | BB1: =SUM(BB5:BB21) -> 0 | BD1: =SUM(BD5:BD21) -> 0 | BF1: =SUM(BF5:BF21) -> 0 | BH1: =SUM(BH5:BH21) -> 0 | BN1: =SUM(BN5:BN21) -> 2320
A2: Date | D2: 45809 | F2: 45810 | H2: 45811 | J2: 45812 | L2: 45813 | N2: 45814 | P2: 45815 | R2: 45816 | T2: 45817 | V2: 45818 | X2: 45819 | Z2: 45820 | AB2: 45821 | AD2: 45822 | AF2: 45823 | AH2: 45824 | AJ2: 45825 | AL2: 45826 | AN2: 45827 | AP2: 45828 | AR2: 45829 | AT2: 45830 | AV2: 45831 | AX2: 45832 | AZ2: 45833 | BB2: 45834 | BD2: 45835 | BF2: 45836 | BH2: 45837 | BJ2: 45838
A3: Shift | D3: sh1 | E3: sh2 | F3: sh1 | G3: sh2 | H3: sh1 | I3: sh2 | J3: sh1 | K3: sh2 | L3: sh1 | M3: sh2 | N3: sh1 | O3: sh2 | P3: sh1 | Q3: sh2 | R3: sh1 | S3: sh2 | T3: sh1 | U3: sh2 | V3: sh1 | W3: sh2 | X3: sh1 | Y3: sh2 | Z3: sh1 | AA3: sh2 | AB3: sh1 | AC3: sh2 | AD3: sh1 | AE3: sh2 | AF3: sh1 | AG3: sh2 | AH3: sh1 | AI3: sh2 | AJ3: sh1 | AK3: sh2 | AL3: sh1 | AM3: sh2 | AN3: sh1 | AO3: sh2 | AP3: sh1 | AQ3: sh2 | AR3: sh1 | AS3: sh2 | AT3: sh1 | AU3: sh2 | AV3: sh1 | AW3: sh2 | AX3: sh1 | AY3: sh2 | AZ3: sh1 | BA3: sh2 | BB3: sh1 | BC3: sh2 | BD3: sh1 | BE3: sh2 | BF3: sh1 | BG3: sh2 | BH3: sh1 | BI3: sh2 | BJ3: sh1 | BK3: sh2 | BL3: sh1 | BM3: sh2
A4: Item code | B4: Item description | C4: Rate | D4: الاحد | F4: الاتنين | H4: الثلاثاء | J4: الاربعاء | L4: الخميس | N4: الجمعة | P4: السبت | R4: الاحد | T4: الاثنين | V4: الثلاثاء | X4: الاربعاء | Z4: الخميس | AB4: الجمعة | AD4: السبت | AF4: الاحد | AH4: الاثنين | AJ4: الثلاثاء | AL4: الاربعاء | AN4: الخميس | AP4: الجمعة | AR4: السبت | AT4: الاحد | AV4: الاثنين | AX4: الثلاثاء | AZ4: الاربعاء | BB4: الخميس | BD4: الجمعة | BF4: السبت | BH4: الاحد | BJ4: الاثنين | BL4: الثلاثاء
A5: =VLOOKUP(B5,#REF!,2,FALSE) -> #REF! | B5: فيفلين بادي اسبلاش كب كيك جلازا 250 مل | C5: 10 | AF5: 408 | BN5: =SUM(D5:BM5) -> 408 | BO5: =COUNT(D5:BM5) -> 1
A6: =VLOOKUP(B6,#REF!,2,FALSE) -> #REF! | B6: فيفلين بادي سبلاش صن كيسد هوني 250 مل | C6: 10 | AF6: 657 | AH6: 383 | AJ6: 436 | AL6: 436 | BN6: =SUM(D6:BM6) -> 1912 | BO6: =COUNT(D6:BM6) -> 4
A7: =VLOOKUP(B7,#REF!,2,FALSE) -> #REF! | C7: 1 | BN7: =SUM(D7:BM7) -> 0 | BO7: =COUNT(D7:BM7) -> 0
A8: =VLOOKUP(B8,#REF!,2,FALSE) -> #REF! | C8: 1 | BN8: =SUM(D8:BM8) -> 0 | BO8: =COUNT(D8:BM8) -> 0
A9: =VLOOKUP(B9,#REF!,2,FALSE) -> #REF! | C9: 1 | BN9: =SUM(D9:BM9) -> 0 | BO9: =COUNT(D9:BM9) -> 0
A10: =VLOOKUP(B10,#REF!,2,FALSE) -> #REF! | C10: 1 | BN10: =SUM(D10:BM10) -> 0 | BO10: =COUNT(D10:BM10) -> 0
A11: =VLOOKUP(B11,#REF!,2,FALSE) -> #REF! | C11: 1 | BN11: =SUM(D11:BM11) -> 0 | BO11: =COUNT(D11:BM11) -> 0
A12: =VLOOKUP(B12,#REF!,2,FALSE) -> #REF! | C12: 1 | BN12: =SUM(D12:BM12) -> 0 | BO12: =COUNT(D12:BM12) -> 0
A13: =VLOOKUP(B13,#REF!,2,FALSE) -> #REF! | C13: 1 | BN13: =SUM(D13:BM13) -> 0 | BO13: =COUNT(D13:BM13) -> 0
A14: =VLOOKUP(B14,#REF!,2,FALSE) -> #REF! | C14: 1 | BN14: =SUM(D14:BM14) -> 0 | BO14: =COUNT(D14:BM14) -> 0
A15: =VLOOKUP(B15,#REF!,2,FALSE) -> #REF! | C15: 1 | BN15: =SUM(D15:BM15) -> 0 | BO15: =COUNT(D15:BM15) -> 0
A16: =VLOOKUP(B16,#REF!,2,FALSE) -> #REF! | C16: 1 | BN16: =SUM(D16:BM16) -> 0 | BO16: =COUNT(D16:BM16) -> 0
A17: =VLOOKUP(B17,#REF!,2,FALSE) -> #REF! | C17: 1 | BN17: =SUM(D17:BM17) -> 0 | BO17: =COUNT(D17:BM17) -> 0
A18: =VLOOKUP(B18,#REF!,2,FALSE) -> #REF! | C18: 1 | BN18: =SUM(D18:BM18) -> 0 | BO18: =COUNT(D18:BM18) -> 0
... A21: =VLOOKUP(B21,#REF!,2,FALSE) -> #REF! | C21: 1 | BN21: =SUM(D21:BM21) -> 0 | BO21: =COUNT(D21:BM21) -> 0
B22: التوالف | D22: =SUM(D23:D31) -> 0 | E22: =SUM(E23:E31) -> 0 | F22: =SUM(F23:F31) -> 0 | G22: =SUM(G23:G31) -> 0 | H22: =SUM(H23:H31) -> 0 | I22: =SUM(I23:I31) -> 0 | J22: =SUM(J23:J31) -> 0 | K22: =SUM(K23:K31) -> 0 | ... BM22: =SUM(BM23:BM31) -> 0 | BN22: =SUM(D22:BM22) -> 0 | BO22: =COUNT(D22:BM22) -> 62
B23: (مورد) | BN23: =SUM(D23:BM23) -> 0 | BO23: =COUNT(D23:BM23) -> 0
B24: عبوة | BN24: =SUM(D24:BM24) -> 0 | BO24: =COUNT(D24:BM24) -> 0
B25: غطاء | BN25: =SUM(D25:BM25) -> 0 | BO25: =COUNT(D25:BM25) -> 0
BN26: =SUM(D26:BM26) -> 0 | BO26: =COUNT(D26:BM26) -> 0
B27: (تشغيل) | BN27: =SUM(D27:BM27) -> 0 | BO27: =COUNT(D27:BM27) -> 0
B28: عبوة | BN28: =SUM(D28:BM28) -> 0 | BO28: =COUNT(D28:BM28) -> 0
B29: غطاء | BN29: =SUM(D29:BM29) -> 0 | BO29: =COUNT(D29:BM29) -> 0
B30: بامب | BN30: =SUM(D30:BM30) -> 0 | BO30: =COUNT(D30:BM30) -> 0
BN31: =SUM(D31:BM31) -> 0 | BO31: =COUNT(D31:BM31) -> 0
B32: Unplanned downtime | D32: =SUM(D33:D116) -> 0 | E32: =SUM(E33:E116) -> 0 | F32: =SUM(F33:F116) -> 0 | G32: =SUM(G33:G116) -> 0 | H32: =SUM(H33:H116) -> 0 | I32: =SUM(I33:I116) -> 0 | J32: =SUM(J33:J116) -> 0 | K32: =SUM(K33:K116) -> 0 | ... BM32: =SUM(BM33:BM116) -> 0 | BN32: =SUM(D32:BM32) -> 0 | BO32: =COUNT(D32:BM32) -> 62
A33: =SUM(BN34:BN52) -> 0 | B33: اعطال الصيانة | BN33: =SUM(D33:BM33) -> 0 | BO33: =COUNT(D33:BM33) -> 0
B34: مشكلة فى النزل | BN34: =SUM(D34:BM34) -> 0 | BO34: =COUNT(D34:BM34) -> 0
B35: مشكلة فى الكامة | BN35: =SUM(D35:BM35) -> 0 | BO35: =COUNT(D35:BM35) -> 0
B36: ضبط الميزان | BN36: =SUM(D36:BM36) -> 0 | BO36: =COUNT(D36:BM36) -> 0
B37: مشكلة فى المكبس | BN37: =SUM(D37:BM37) -> 0 | BO37: =COUNT(D37:BM37) -> 0
B38: تسريب الخامة من العبوات | BN38: =SUM(D38:BM38) -> 0 | BO38: =COUNT(D38:BM38) -> 0
B39: مشكة فى ضغط العبوات (اللحام) | BN39: =SUM(D39:BM39) -> 0 | BO39: =COUNT(D39:BM39) -> 0
B40: مشكلة فى السخانات | BN40: =SUM(D40:BM40) -> 0 | BO40: =COUNT(D40:BM40) -> 0
B41: ضبط الكاميرا | BN41: =SUM(D41:BM41) -> 0 | BO41: =COUNT(D41:BM41) -> 0
B42: تغيير حجم المنتج على الماكينة | BN42: =SUM(D42:BM42) -> 0 | BO42: =COUNT(D42:BM42) -> 0
...

Sheet Codes
C3: مشكلة فى النزل | E3: Machine failure | F3: MF1
C4: ضبط الميزان | E4: Set up& adjustment | F4: ADJ1
C5: مشكلة فى الميزان | E5: Machine failure | F5: MF2
C6: مشكلة فى المكبس | E6: Machine failure | F6: MF3
C7: تسريب الخامة من العبوات | E7: Machine failure | F7: MF4
C8: مشكة فى ضغط العبوات (اللحام) | E8: Machine failure | F8: MF5
C9: مشكلة فى السخانات | E9: Machine failure | F9: MF6
C10: ضبط الكاميرا | E10: Machine failure | F10: MF7
C11: ضبط الكاميرا | E11: Quality losses | F11: Q1
C12: مشكله في ضغط الهواء (فى الكومبرسور) | E12: utility loss | F12: UT1
C13: مشكله في خرطوم الهواء | E13: Machine failure | F13: MF8
C14: ضبط اعدادات الماكينة | E14: Machine failure | F14: MF9
... C34: تغيير شريط لحام | E34: minor losses | F34: MIN4
B35: اعطال الانتاج | C35: ضبط الكاميرا | E35: Set up& adjustment | F35: ADJ9
C36: اعطال النقل من مكان لاخر | E36: Management loss | F36: MG1
C37: عمال غير مدربة | E37: Management loss | F37: MG2
C38: تنظيف الماكينة | E38: Management loss | F38: MG3
C39: تنظيف بستم الفويل | E39: Management loss | F39: MG4
C40: تنظيف سير نقل المنتج | E40: Management loss | F40: MG5
C41: الوقوف على العبوات المجهزة | E41: Management loss | F41: MG6
C42: تأخير صرف المستلزمات | E42: Management loss | F42: MG7
C43: عدم وجود عمالة كافية | E43: Management loss | F43: MG8
C44: تغيير رقم التشغيلة/التانك | E44: Set up& adjustment | F44: ADJ10
C45: تعبئة | E45: minor losses | F45: MIN1
C46: اعطال خط التغليف | E46: Management loss | F46: MG9
C47: تغيير حجم المنتج على الماكينة | E47: Start up loss | F47: SU1
... C58: التشغيل بسرعة اقل | E58: Management loss | F58: MIN2
B59: أعطال التخطيط | C59: الوقوف على المستلزمات (تخطيط) | E59: Management loss | F59: MG10
C60: تغيير فى الـ BOM | E60: Management loss | F60: MG14
B61: أعطال المخزن | C61: الوقوف على المستلزمات (مخزن) | E61: Management loss | F61: MG11
B62: أعطال الجودة | C62: مشكلة فى العبوات | E62: Quality losses | F62: Q4
C63: مشكلة فى الخامة | E63: Quality losses | F63: Q5
C64: مشكلة فى السليف | E64: Quality losses | F64: Q6
C65: مشكلة فى الاستيكر | E65: Quality losses | F65: Q7
C66: تأخير محضر فحص | E66: Quality losses | F66: Q8
C67: تأخير محضر فحص | E67: Management loss | F67: MG12
B68: أعطال التصنيع | C68: الوقوف على الخامة | E68: Management loss | F68: MG13
C69: مشكلة فى الخامة | E69: Quality losses | F69: Q9
C70: وجود فوم فى الخامة | E70: Quality losses | F70: Q10
C71: Changeover | E71: Start up loss | F71: SU4

Sheet Week Dashboard
B2: Week-3 | J2: Week-4
B3: OEE Dashboard | J3: OEE Dashboard
B4: s | C4: Machine name | D4: availability | E4: Performance | F4: Quality | G4: OEE | H4: Target | I4: Gap | J4: s | K4: Machine name | L4: availability | M4: Performance | N4: Quality | O4: OEE | P4: Target | Q4: Gap
B5: 1 | C5: Nordon | D5: =#REF! -> #REF! | E5: =#REF! -> #REF! | F5: =#REF! -> #REF! | G5: =D5*E5*F5 -> #REF! | H5: 0.8 | I5: =H5-G5 -> #REF! | J5: 1 | K5: Nordon | L5: =#REF! -> #REF! | M5: =#REF! -> #REF! | N5: =#REF! -> #REF! | O5: =L5*M5*N5 -> #REF! | P5: 0.8 | Q5: =P5-O5 -> #REF!
B6: 2 | C6: Kadico | D6: =#REF! -> #REF! | E6: =#REF! -> #REF! | F6: =#REF! -> #REF! | G6: =D6*E6*F6 -> #REF! | H6: 0.8 | I6: =H6-G6 -> #REF! | J6: 2 | K6: Kadico | L6: =#REF! -> #REF! | M6: =#REF! -> #REF! | N6: =#REF! -> #REF! | O6: =L6*M6*N6 -> #REF! | P6: 0.8 | Q6: =P6-O6 -> #REF!
B7: 3 | C7: Kalix | D7: =#REF! -> #REF! | E7: =#REF! -> #REF! | F7: =#REF! -> #REF! | G7: =D7*E7*F7 -> #REF! | H7: 0.8 | I7: =H7-G7 -> #REF! | J7: 3 | K7: Kalix | L7: =#REF! -> #REF! | M7: =#REF! -> #REF! | N7: =#REF! -> #REF! | O7: =L7*M7*N7 -> #REF! | P7: 0.8 | Q7: =P7-O7 -> #REF!
B8: 4 | C8: Cream 1 | D8: =#REF! -> #REF! | E8: =#REF! -> #REF! | F8: =#REF! -> #REF! | G8: =D8*E8*F8 -> #REF! | H8: 0.8 | I8: =H8-G8 -> #REF! | J8: 4 | K8: Cream 1 | L8: =#REF! -> #REF! | M8: =#REF! -> #REF! | N8: =#REF! -> #REF! | O8: =L8*M8*N8 -> #REF! | P8: 0.8 | Q8: =P8-O8 -> #REF!
B9: 5 | C9: 4 Nozzole | D9: =#REF! -> #REF! | E9: =#REF! -> #REF! | F9: =#REF! -> #REF! | G9: =D9*E9*F9 -> #REF! | H9: 0.8 | I9: =H9-G9 -> #REF! | J9: 5 | K9: 4 Nozzole | L9: =#REF! -> #REF! | M9: =#REF! -> #REF! | N9: =#REF! -> #REF! | O9: =L9*M9*N9 -> #REF! | P9: 0.8 | Q9: =P9-O9 -> #REF!
B10: 6 | C10: Cream 2 | D10: =#REF! -> #REF! | E10: =#REF! -> #REF! | F10: =#REF! -> #REF! | G10: =D10*E10*F10 -> #REF! | H10: 0.8 | I10: =H10-G10 -> #REF! | J10: 6 | K10: Cream 2 | L10: =#REF! -> #REF! | M10: =#REF! -> #REF! | N10: =#REF! -> #REF! | O10: =L10*M10*N10 -> #REF! | P10: 0.8 | Q10: =P10-O10 -> #REF!
B11: 7 | C11: Rotary | D11: =#REF! -> #REF! | E11: =#REF! -> #REF! | F11: =#REF! -> #REF! | G11: =D11*E11*F11 -> #REF! | H11: 0.8 | I11: =H11-G11 -> #REF! | J11: 7 | K11: Rotary | L11: =#REF! -> #REF! | M11: =#REF! -> #REF! | N11: =#REF! -> #REF! | O11: =L11*M11*N11 -> #REF! | P11: 0.8 | Q11: =P11-O11 -> #REF!
B12: 8 | C12: 8 Nozzole | D12: =#REF! -> #REF! | E12: =#REF! -> #REF! | F12: =#REF! -> #REF! | G12: =D12*E12*F12 -> #REF! | H12: 0.8 | I12: =H12-G12 -> #REF! | J12: 8 | K12: 8 Nozzole | L12: =#REF! -> #REF! | M12: =#REF! -> #REF! | N12: =#REF! -> #REF! | O12: =L12*M12*N12 -> #REF! | P12: 0.8 | Q12: =P12-O12 -> #REF!
B13: 9 | C13: 6 Nozzole (Old) | D13: =#REF! -> #REF! | E13: =#REF! -> #REF! | F13: =#REF! -> #REF! | G13: =D13*E13*F13 -> #REF! | H13: 0.8 | I13: =H13-G13 -> #REF! | J13: 9 | K13: 6 Nozzole (Old) | L13: =#REF! -> #REF! | M13: =#REF! -> #REF! | N13: =#REF! -> #REF! | O13: =L13*M13*N13 -> #REF! | P13: 0.8 | Q13: =P13-O13 -> #REF!
B14: 10 | C14: 6 Nozzole (New) | D14: =#REF! -> #REF! | E14: =#REF! -> #REF! | F14: =#REF! -> #REF! | G14: =D14*E14*F14 -> #REF! | H14: 0.8 | I14: =H14-G14 -> #REF! | J14: 10 | K14: 6 Nozzole (New) | L14: =#REF! -> #REF! | M14: =#REF! -> #REF! | N14: =#REF! -> #REF! | O14: =L14*M14*N14 -> #REF! | P14: 0.8 | Q14: =P14-O14 -> #REF!
B15: 11 | C15: Roll-on | D15: =#REF! -> #REF! | E15: =#REF! -> #REF! | F15: =#REF! -> #REF! | G15: =D15*E15*F15 -> #REF! | H15: 0.8 | I15: =H15-G15 -> #REF! | J15: 11 | K15: Roll-on | L15: =#REF! -> #REF! | M15: =#REF! -> #REF! | N15: =#REF! -> #REF! | O15: =L15*M15*N15 -> #REF! | P15: 0.8 | Q15: =P15-O15 -> #REF!
B16: 12 | C16: Sachet (Old) | D16: =#REF! -> #REF! | E16: =#REF! -> #REF! | F16: =#REF! -> #REF! | G16: =D16*E16*F16 -> #REF! | H16: 0.8 | I16: =H16-G16 -> #REF! | J16: 12 | K16: Sachet (Old)
B17: 13 | C17: Sachet (New) | D17: =#REF! -> #REF! | E17: =#REF! -> #REF! | F17: =#REF! -> #REF! | G17: =D17*E17*F17 -> #REF! | H17: 0.8 | I17: =H17-G17 -> #REF! | J17: 13 | K17: Sachet (New) | L17: =#REF! -> #REF! | M17: =#REF! -> #REF! | N17: =#REF! -> #REF! | O17: =L17*M17*N17 -> #REF! | P17: 0.8 | Q17: =P17-O17 -> #REF!
B18: 14 | C18: 1 Nozzole | D18: =#REF! -> #REF! | E18: =#REF! -> #REF! | F18: =#REF! -> #REF! | G18: =D18*E18*F18 -> #REF! | H18: 0.8 | I18: =H18-G18 -> #REF! | J18: 14 | K18: 1 Nozzole
B19: 15 | C19: Wax-line | J19: 15 | K19: Wax-line
B20: 16 | C20: Lip Balm (Old) | D20: =#REF! -> #REF! | E20: =#REF! -> #REF! | F20: =#REF! -> #REF! | G20: =D20*E20*F20 -> #REF! | H20: 0.8 | I20: =H20-G20 -> #REF! | J20: 16 | K20: Lip Balm (Old) | L20: =#REF! -> #REF! | M20: =#REF! -> #REF! | N20: =#REF! -> #REF! | O20: =L20*M20*N20 -> #REF! | P20: 0.8 | Q20: =P20-O20 -> #REF!
B21: 17 | C21: Lip Balm (New) | D21: =#REF! -> #REF! | E21: =#REF! -> #REF! | F21: =#REF! -> #REF! | G21: =D21*E21*F21 -> #REF! | H21: 0.8 | I21: =H21-G21 -> #REF! | J21: 17 | K21: Lip Balm (New) | L21: =#REF! -> #REF! | M21: =#REF! -> #REF! | N21: =#REF! -> #REF! | O21: =L21*M21*N21 -> #REF! | P21: 0.8 | Q21: =P21-O21 -> #REF!
B22: 18 | C22: Scrub | J22: 18 | K22: Scrub | L22: =#REF! -> #REF! | M22: =#REF! -> #REF! | N22: =#REF! -> #REF! | O22: =L22*M22*N22 -> #REF! | P22: 0.8 | Q22: =P22-O22 -> #REF!
B23: 19 | C23: Old Kalix | D23: =#REF! -> #REF! | E23: =#REF! -> #REF! | F23: =#REF! -> #REF! | G23: =D23*E23*F23 -> #REF! | H23: 0.8 | I23: =H23-G23 -> #REF! | J23: 19 | K23: Old Kalix
B24: Average | G24: =AVERAGE(G5:G23) -> #REF! | H24: 0.8 | I24: =H24-G24 -> #REF! | J24: Average | O24: =AVERAGE(O5:O23) -> #REF! | P24: 0.8 | Q24: =P24-O24 -> #REF!

Sheet NORDON
F1: =SUM(F5:F17) -> 10900 | G1: =SUM(G5:G17) -> 8172 | H1: =SUM(H5:H17) -> 10437 | I1: =SUM(I5:I17) -> 9070 | J1: =SUM(J5:J17) -> 11550 | K1: =SUM(K5:K17) -> 6575 | L1: =SUM(L5:L17) -> 0 | M1: =SUM(M5:M17) -> 0 | ... BJ1: =SUM(BJ5:BJ17) -> 92879
C2: Date | F2: 46082 | H2: 46083 | J2: 46084 | L2: 46085 | N2: 46086 | P2: 46087 | R2: 46088 | T2: 46089 | V2: 46090 | X2: 46091 | Z2: 46092 | AB2: 46093 | AD2: 46094 | AF2: 46095 | AH2: 46096 | AJ2: 46097 | AL2: 46098 | AN2: 46099 | AP2: 46100 | AR2: 46101 | AT2: 46102 | AV2: 46103 | AX2: 46104 | AZ2: 46105 | BB2: 46106 | BD2: 46107 | BF2: 46108 | BH2: 46109
C3: Shift | F3: sh1 | G3: sh2 | H3: sh1 | I3: sh2 | J3: sh1 | K3: sh2 | L3: sh1 | M3: sh2 | N3: sh1 | O3: sh2 | P3: sh1 | Q3: sh2 | R3: sh1 | S3: sh2 | T3: sh1 | U3: sh2 | V3: sh1 | W3: sh2 | X3: sh1 | Y3: sh2 | Z3: sh1 | AA3: sh2 | AB3: sh1 | AC3: sh2 | AD3: sh1 | AE3: sh2 | AF3: sh1 | AG3: sh2 | AH3: sh1 | AI3: sh2 | AJ3: sh1 | AK3: sh2 | AL3: sh1 | AM3: sh2 | AN3: sh1 | AO3: sh2 | AP3: sh1 | AQ3: sh2 | AR3: sh1 | AS3: sh2 | AT3: sh1 | AU3: sh2 | AV3: sh1 | AW3: sh2 | AX3: sh1 | AY3: sh2 | AZ3: sh1 | BA3: sh2 | BB3: sh1 | BC3: sh2 | BD3: sh1 | BE3: sh2 | BF3: sh1 | BG3: sh2 | BH3: sh1 | BI3: sh2
C4: Item code | D4: Item description | E4: Rate | F4: الاحد | H4: الاثنين | J4: الثلاثاء | L4: الاربعاء | N4: الخميس | P4: الجمعة | R4: السبت | T4: الاحد | V4: الاثنين | X4: الثلاثاء | Z4: الاربعاء | AB4: الخميس | AD4: الجمعة | AF4: السبت | AH4: الاحد | AJ4: الاثنين | AL4: الثلاثاء | AN4: الاربعاء | AP4: الخميس | AR4: الجمعة | AT4: السبت | AV4: الاحد | AX4: الاثنين | AZ4: الثلاثاء | BB4: الاربعاء | BD4: الخميس | BF4: الجمعة | BH4: السبت
C5: =VLOOKUP(D5,Products!B:D,2,FALSE) -> 41813002 | D5: كير اند مور بودي لوشن برائحة الفراولة 150مل | E5: 40 | F5: 10900 | G5: 8172 | H5: 10437 | BJ5: =SUM(F5:BI5) -> 29509 | BK5: =COUNT(F5:BI5) -> 3
C6: =VLOOKUP(D6,Products!B:D,2,FALSE) -> 41813001 | D6: كير اند مور بودي لوشن برائحة جوز الهند 150مل | E6: 40 | I6: 9070 | J6: 7422 | BJ6: =SUM(F6:BI6) -> 16492 | BK6: =COUNT(F6:BI6) -> 2
C7: =VLOOKUP(D7,Products!B:D,2,FALSE) -> 41814002 | D7: كير اند مور غسول الوجة للبشره الدهنيه بالصبار 150مل | E7: 40 | J7: 4128 | BJ7: =SUM(F7:BI7) -> 4128 | BK7: =COUNT(F7:BI7) -> 1
C8: =VLOOKUP(D8,Products!B:D,2,FALSE) -> 41814001 | D8: كير اند مور غسول الوجه للبشره الجافة والعادية 150مل | E8: 40 | K8: 6575 | BJ8: =SUM(F8:BI8) -> 6575 | BK8: =COUNT(F8:BI8) -> 1
C9: =VLOOKUP(D9,Products!B:D,2,FALSE) -> #N/A | D9: زوريا كريم مقشر للوجه 100مل | E9: 40 | N9: 2127 | T9: 870 | BJ9: =SUM(F9:BI9) -> 2997 | BK9: =COUNT(F9:BI9) -> 2
C10: =VLOOKUP(D10,Products!B:D,2,FALSE) -> 41813004 | D10: كير اند مور بودي لوشن برائحة التوت 150مل | E10: 40 | V10: 4933 | BJ10: =SUM(F10:BI10) -> 4933 | BK10: =COUNT(F10:BI10) -> 1
C11: =VLOOKUP(D11,Products!B:D,2,FALSE) -> 41500029 | D11: مان زون فايبر جل الشفاف – اكسترا سترونج هولد 175 مل | E11: 35 | X11: 3730 | Z11: 6429 | BJ11: =SUM(F11:BI11) -> 10159 | BK11: =COUNT(F11:BI11) -> 2
C12: =VLOOKUP(D12,Products!B:D,2,FALSE) -> 41500002 | D12: Man-Zone Fiber gel Wet effect - 175ml | E12: 35 | Z12: =95+881 -> 976 | AB12: 10800 | BJ12: =SUM(F12:BI12) -> 11776 | BK12: =COUNT(F12:BI12) -> 2
C13: =VLOOKUP(D13,Products!B:D,2,FALSE) -> #N/A | D13: زوريا هاند كريم 100مل | E13: 35 | AF13: 3225 | BJ13: =SUM(F13:BI13) -> 3225 | BK13: =COUNT(F13:BI13) -> 1
C14: =VLOOKUP(D14,Products!B:D,2,FALSE) -> #N/A | D14: zuriya facial cleanser 150ml | E14: 35 | AF14: 200 | AH14: 2885 | BJ14: =SUM(F14:BI14) -> 3085 | BK14: =COUNT(F14:BI14) -> 2
C15: =VLOOKUP(D15,Products!B:D,2,FALSE) -> #N/A | E15: 1 | BJ15: =SUM(F15:BI15) -> 0 | BK15: =COUNT(F15:BI15) -> 0
C16: =VLOOKUP(D16,Products!B:D,2,FALSE) -> #N/A | E16: 1 | BJ16: =SUM(F16:BI16) -> 0 | BK16: =COUNT(F16:BI16) -> 0
C17: =VLOOKUP(D17,Products!B:D,2,FALSE) -> #N/A | E17: 1 | BJ17: =SUM(F17:BI17) -> 0 | BK17: =COUNT(F17:BI17) -> 0
D18: التوالف | F18: =SUM(F19:F27) -> 0 | G18: =SUM(G19:G27) -> 43 | H18: =SUM(H19:H27) -> 0 | I18: =SUM(I19:I27) -> 0 | J18: =SUM(J19:J27) -> 21 | K18: =SUM(K19:K27) -> 0 | L18: =SUM(L19:L27) -> 0 | M18: =SUM(M19:M27) -> 0 | ... AY18: =SUM(AY19:AY27) -> 0 | BA18: =SUM(BA19:BA27) -> 0 | BB18: =SUM(BB19:BB27) -> 0 | BC18: =SUM(BC19:BC27) -> 0 | BD18: =SUM(BD19:BD27) -> 0 | BE18: =SUM(BE19:BE27) -> 0 | BF18: =SUM(BF19:BF27) -> 0 | BG18: =SUM(BG19:BG27) -> 0 | BH18: =SUM(BH19:BH27) -> 0 | BI18: =SUM(BI19:BI27) -> 0 | BJ18: =SUM(F18:BI18) -> 249 | BK18: =COUNT(F18:BI18) -> 55
D19: (مورد) | BJ19: =SUM(F19:BI19) -> 0 | BK19: =COUNT(F19:BI19) -> 0
D20: عبوة | G20: 38 | J20: 3 | BJ20: =SUM(F20:BI20) -> 41 | BK20: =COUNT(F20:BI20) -> 2
D21: غطاء | BJ21: =SUM(F21:BI21) -> 0 | BK21: =COUNT(F21:BI21) -> 0
BJ22: =SUM(F22:BI22) -> 0 | BK22: =COUNT(F22:BI22) -> 0
D23: (تشغيل) | BJ23: =SUM(F23:BI23) -> 0 | BK23: =COUNT(F23:BI23) -> 0
D24: عبوة | G24: 5 | J24: 18 | N24: 59 | T24: 24 | V24: 9 | X24: 24 | Z24: 37 | AB24: 32 | BJ24: =SUM(F24:BI24) -> 208 | BK24: =COUNT(F24:BI24) -> 8
D25: غطاء | BJ25: =SUM(F25:BI25) -> 0 | BK25: =COUNT(F25:BI25) -> 0
D26: بامب | BJ26: =SUM(F26:BI26) -> 0 | BK26: =COUNT(F26:BI26) -> 0
BJ27: =SUM(F27:BI27) -> 0 | BK27: =COUNT(F27:BI27) -> 0
D28: Unplanned downtime | F28: =SUM(F29:F106) -> 0 | G28: =SUM(G29:G106) -> 45 | H28: =SUM(H29:H106) -> 45 | I28: =SUM(I29:I106) -> 15 | J28: =SUM(J29:J106) -> 60 | K28: =SUM(K29:K106) -> 0 | L28: =SUM(L29:L106) -> 0 | M28: =SUM(M29:M106) -> 0 | ... O28: =SUM(O29:O106) -> 0 | R28: =SUM(R29:R106) -> 0 | S28: =SUM(S29:S106) -> 0 | T28: =SUM(T29:T106) -> 0 | U28: =SUM(U29:U106) -> 0 | V28: =SUM(V29:V106) -> 0 | W28: =SUM(W29:W106) -> 0 | X28: =SUM(X29:X106) -> 127 | Y28: =SUM(Y29:Y106) -> 0 | ... AY28: =SUM(AY29:AY106) -> 0 | BA28: =SUM(BA29:BA106) -> 0 | BB28: =SUM(BB29:BB106) -> 0 | BC28: =SUM(BC29:BC106) -> 0 | BD28: =SUM(BD29:BD106) -> 0 | BE28: =SUM(BE29:BE106) -> 0 | BF28: =SUM(BF29:BF106) -> 0 | BG28: =SUM(BG29:BG106) -> 0 | BH28: =SUM(BH29:BH106) -> 0 | BI28: =SUM(BI29:BI106) -> 0 | BJ28: =SUM(F28:BI28) -> 630 | BK28: =COUNT(F28:BI28) -> 53
C29: =SUM(BJ30:BJ49) -> 35 | D29: اعطال الصيانة | BJ29: =SUM(F29:BI29) -> 0 | BK29: =COUNT(F29:BI29) -> 0
B30: Machine failure | C30: MF1 | D30: مشكلة فى النزل | BJ30: =SUM(F30:BI30) -> 0 | BK30: =COUNT(F30:BI30) -> 0
B31: Set up& adjustment | C31: ADJ1 | D31: ضبط الميزان | BJ31: =SUM(F31:BI31) -> 0 | BK31: =COUNT(F31:BI31) -> 0
B32: Machine failure | C32: MF2 | D32: مشكلة فى الميزان | BJ32: =SUM(F32:BI32) -> 0 | BK32: =COUNT(F32:BI32) -> 0
B33: Machine failure | C33: MF3 | D33: مشكلة فى المكبس | BJ33: =SUM(F33:BI33) -> 0 | BK33: =COUNT(F33:BI33) -> 0
B34: Machine failure | C34: MF4 | D34: تسريب الخامة من العبوات | N34: 10 | BJ34: =SUM(F34:BI34) -> 10 | BK34: =COUNT(F34:BI34) -> 1
B35: Machine failure | C35: MF5 | D35: مشكة فى ضغط العبوات (اللحام) | BJ35: =SUM(F35:BI35) -> 0 | BK35: =COUNT(F35:BI35) -> 0
B36: Machine failure | C36: MF6 | D36: مشكلة فى السخانات | N36: 15 | BJ36: =SUM(F36:BI36) -> 15 | BK36: =COUNT(F36:BI36) -> 1
B37: Machine failure | C37: MF7 | D37: ضبط الكاميرا | N37: 10 | BJ37: =SUM(F37:BI37) -> 10 | BK37: =COUNT(F37:BI37) -> 1
B38: Quality losses | C38: Q1 | D38: ضبط الكاميرا | BJ38: =SUM(F38:BI38) -> 0 | BK38: =COUNT(F38:BI38) -> 0
B39: utility loss | C39: UT1 | D39: مشكله في ضغط الهواء (فى الكومبرسور) | BJ39: =SUM(F39:BI39) -> 0 | BK39: =COUNT(F39:BI39) -> 0
B40: Machine failure | C40: MF8 | D40: مشكله في خرطوم الهواء | BJ40: =SUM(F40:BI40) -> 0 | BK40: =COUNT(F40:BI40) -> 0
...

Sheet KALEKS
F1: =SUM(F5:F14) -> 15200 | G1: =SUM(G5:G14) -> 13686 | H1: =SUM(H5:H14) -> 15341 | I1: =SUM(I5:I14) -> 11675 | J1: =SUM(J5:J14) -> 10200 | K1: =SUM(K5:K14) -> 13170 | L1: =SUM(L5:L14) -> 16800 | M1: =SUM(M5:M14) -> 13259 | ... BJ1: =SUM(BJ5:BJ14) -> 328676
C2: Date | F2: 46082 | H2: 46083 | J2: 46084 | L2: 46085 | N2: 46086 | P2: 46087 | R2: 46088 | T2: 46089 | V2: 46090 | X2: 46091 | Z2: 46092 | AB2: 46093 | AD2: 46094 | AF2: 46095 | AH2: 46096 | AJ2: 46097 | AL2: 46098 | AN2: 46099 | AP2: 46100 | AR2: 46101 | AT2: 46102 | AV2: 46103 | AX2: 46104 | AZ2: 46105 | BB2: 46106 | BD2: 46107 | BF2: 46108 | BH2: 46109
C3: Shift | F3: sh1 | G3: sh2 | H3: sh1 | I3: sh2 | J3: sh1 | K3: sh2 | L3: sh1 | M3: sh2 | N3: sh1 | O3: sh2 | P3: sh1 | Q3: sh2 | R3: sh1 | S3: sh2 | T3: sh1 | U3: sh2 | V3: sh1 | W3: sh2 | X3: sh1 | Y3: sh2 | Z3: sh1 | AA3: sh2 | AB3: sh1 | AC3: sh2 | AD3: sh1 | AE3: sh2 | AF3: sh1 | AG3: sh2 | AH3: sh1 | AI3: sh2 | AJ3: sh1 | AK3: sh2 | AL3: sh1 | AM3: sh2 | AN3: sh1 | AO3: sh2 | AP3: sh1 | AQ3: sh2 | AR3: sh1 | AS3: sh2 | AT3: sh1 | AU3: sh2 | AV3: sh1 | AW3: sh2 | AX3: sh1 | AY3: sh2 | AZ3: sh1 | BA3: sh2 | BB3: sh1 | BC3: sh2 | BD3: sh1 | BE3: sh2 | BF3: sh1 | BG3: sh2 | BH3: sh1 | BI3: sh2
C4: Item code | D4: Item description | E4: Rate | F4: الاحد | H4: الاثنين | J4: الثلاثاء | L4: الاربعاء | N4: الخميس | P4: الجمعة | R4: السبت | T4: الاحد | V4: الاثنين | X4: الثلاثاء | Z4: الاربعاء | AB4: الخميس | AD4: الجمعة | AF4: السبت | AH4: الاحد | AJ4: الاثنين | AL4: الثلاثاء | AN4: الاربعاء | AP4: الخميس | AR4: الجمعة | AT4: السبت | AV4: الاحد | AX4: الاثنين | AZ4: الثلاثاء | BB4: الاربعاء | BD4: الخميس | BF4: الجمعة | BH4: السبت
C5: =VLOOKUP(D5,Products!B:D,2,FALSE) -> 40740030 | D5: فيبكس كلاسيك 15 جم الشكل الجديد | E5: 49 | F5: 15200 | G5: 6136 | J5: 10200 | X5: 3500 | Y5: 12000 | Z5: 940 | BJ5: =SUM(F5:BI5) -> 47976 | BK5: =COUNT(F5:BI5) -> 6
C6: =VLOOKUP(D6,Products!B:D,2,FALSE) -> 40740033 | D6: فيبكس كلاسيك 25 جم الشكل الجديد | E6: 49 | G6: 7550 | H6: 15341 | I6: 11675 | BJ6: =SUM(F6:BI6) -> 34566 | BK6: =COUNT(F6:BI6) -> 3
C7: =VLOOKUP(D7,Products!B:D,2,FALSE) -> 40740027 | D7: فيبكس كلاسيك 10 جم الشكل الجديد | E7: 49 | K7: 13170 | L7: 16800 | Z7: 11150 | AB7: 8500 | AC7: 17710 | AF7: 18000 | AG7: 17500 | BJ7: =SUM(F7:BI7) -> 102830 | BK7: =COUNT(F7:BI7) -> 7
C8: =VLOOKUP(D8,Products!B:D,2,FALSE) -> 40740028 | D8: فيبكس رجالي 10 جم الشكل الجديد | E8: 49 | M8: 13259 | N8: 16750 | AA8: 16000 | BJ8: =SUM(F8:BI8) -> 46009 | BK8: =COUNT(F8:BI8) -> 3
C9: =VLOOKUP(D9,Products!B:D,2,FALSE) -> 40740029 | D9: فيبكس حريمي 10 جم الشكل الجديد | E9: 49 | O9: 13320 | T9: 17000 | U9: 10130 | BJ9: =SUM(F9:BI9) -> 40450 | BK9: =COUNT(F9:BI9) -> 3
C10: =VLOOKUP(D10,Products!B:D,2,FALSE) -> 40740032 | D10: فيبكس حريمي 15 جم الشكل الجديد | E10: 49 | U10: 5600 | V10: 16500 | W10: 6135 | BJ10: =SUM(F10:BI10) -> 28235 | BK10: =COUNT(F10:BI10) -> 3
C11: =VLOOKUP(D11,Products!B:D,2,FALSE) -> 40740031 | D11: فيبكس رجالي 15 جم الشكل الجديد | E11: 49 | W11: 10000 | X11: 11500 | AB11: 7110 | BJ11: =SUM(F11:BI11) -> 28610 | BK11: =COUNT(F11:BI11) -> 3
C12: =VLOOKUP(D12,Products!B:D,2,FALSE) -> #N/A | E12: 1 | BJ12: =SUM(F12:BI12) -> 0 | BK12: =COUNT(F12:BI12) -> 0
C13: =VLOOKUP(D13,Products!B:D,2,FALSE) -> #N/A | E13: 1 | BJ13: =SUM(F13:BI13) -> 0 | BK13: =COUNT(F13:BI13) -> 0
C14: =VLOOKUP(D14,Products!B:D,2,FALSE) -> #N/A | E14: 1 | BJ14: =SUM(F14:BI14) -> 0 | BK14: =COUNT(F14:BI14) -> 0
D15: التوالف | F15: =SUM(F16:F23) -> 62 | G15: =SUM(G16:G23) -> 19 | H15: =SUM(H16:H23) -> 197 | I15: =SUM(I16:I23) -> 68 | J15: =SUM(J16:J23) -> 106 | K15: =SUM(K16:K23) -> 90 | L15: =SUM(L16:L23) -> 10 | M15: =SUM(M16:M23) -> 36 | ... BI15: =SUM(BI16:BI23) -> 0 | BJ15: =SUM(F15:BI15) -> 1144 | BK15: =COUNT(F15:BI15) -> 56
D16: (مورد) | BJ16: =SUM(F16:BI16) -> 0 | BK16: =COUNT(F16:BI16) -> 0
D17: عبوة | I17: 25 | K17: 35 | M17: 12 | BJ17: =SUM(F17:BI17) -> 72 | BK17: =COUNT(F17:BI17) -> 3
D18: غطاء | BJ18: =SUM(F18:BI18) -> 0 | BK18: =COUNT(F18:BI18) -> 0
BJ19: =SUM(F19:BI19) -> 0 | BK19: =COUNT(F19:BI19) -> 0
D20: (تشغيل) | BJ20: =SUM(F20:BI20) -> 0 | BK20: =COUNT(F20:BI20) -> 0
D21: عبوة | F21: 62 | G21: 19 | H21: 197 | I21: 43 | J21: 106 | K21: 55 | L21: 10 | M21: 24 | N21: 27 | O21: 16 | T21: 117 | U21: 13 | V21: 107 | W21: 36 | X21: 47 | Y21: 45 | Z21: 32 | AA21: 40 | AB21: 9 | AC21: 8 | AF21: 47 | AG21: 12 | BJ21: =SUM(F21:BI21) -> 1072 | BK21: =COUNT(F21:BI21) -> 22
D22: غطاء | BJ22: =SUM(F22:BI22) -> 0 | BK22: =COUNT(F22:BI22) -> 0
D23: بامب | BJ23: =SUM(F23:BI23) -> 0 | BK23: =COUNT(F23:BI23) -> 0
D24: Unplanned downtime | F24: =SUM(F25:F102) -> 0 | G24: =SUM(G25:G102) -> 25 | H24: =SUM(H25:H102) -> 0 | I24: =SUM(I25:I102) -> 35 | J24: =SUM(J25:J102) -> 127 | K24: =SUM(K25:K102) -> 57 | L24: =SUM(L25:L102) -> 0 | M24: =SUM(M25:M102) -> 20 | ... BI24: =SUM(BI25:BI102) -> 0 | BJ24: =SUM(F24:BI24) -> 564 | BK24: =COUNT(F24:BI24) -> 56
C25: =SUM(BJ26:BJ45) -> 192 | D25: اعطال الصيانة | BJ25: =SUM(F25:BI25) -> 0 | BK25: =COUNT(F25:BI25) -> 0
B26: Machine failure | C26: MF1 | D26: مشكلة فى النزل | BJ26: =SUM(F26:BI26) -> 0 | BK26: =COUNT(F26:BI26) -> 0
B27: Set up& adjustment | C27: ADJ1 | D27: ضبط الميزان | BJ27: =SUM(F27:BI27) -> 0 | BK27: =COUNT(F27:BI27) -> 0
B28: Machine failure | C28: MF2 | D28: مشكلة فى الميزان | BJ28: =SUM(F28:BI28) -> 0 | BK28: =COUNT(F28:BI28) -> 0
B29: Machine failure | C29: MF3 | D29: مشكلة فى المكبس/ذراع العبوات | G29: 25 | BJ29: =SUM(F29:BI29) -> 25 | BK29: =COUNT(F29:BI29) -> 1
B30: Machine failure | C30: MF4 | D30: تسريب الخامة من العبوات | BJ30: =SUM(F30:BI30) -> 0 | BK30: =COUNT(F30:BI30) -> 0
B31: Machine failure | C31: MF5 | D31: مشكة فى ضغط العبوات (اللحام) | BJ31: =SUM(F31:BI31) -> 0 | BK31: =COUNT(F31:BI31) -> 0
B32: Machine failure | C32: MF6 | D32: مشكلة فى السخانات | K32: 20 | N32: 15 | BJ32: =SUM(F32:BI32) -> 35 | BK32: =COUNT(F32:BI32) -> 2
B33: Machine failure | C33: MF7 | D33: ضبط الكاميرا | J33: 15 | K33: 17 | AA33: 10 | BJ33: =SUM(F33:BI33) -> 42 | BK33: =COUNT(F33:BI33) -> 3
B34: Quality losses | C34: Q1 | D34: ضبط الكاميرا | BJ34: =SUM(F34:BI34) -> 0 | BK34: =COUNT(F34:BI34) -> 0
B35: utility loss | C35: UT1 | D35: مشكله في ضغط الهواء (فى الكومبرسور) | Y35: 90 | BJ35: =SUM(F35:BI35) -> 90 | BK35: =COUNT(F35:BI35) -> 1
B36: Machine failure | C36: MF8 | D36: مشكله في خرطوم الهواء | BJ36: =SUM(F36:BI36) -> 0 | BK36: =COUNT(F36:BI36) -> 0
B37: Machine failure | C37: MF9 | D37: ضبط اعدادات الماكينة | BJ37: =SUM(F37:BI37) -> 0 | BK37: =COUNT(F37:BI37) -> 0
B38: Machine failure | C38: MF10 | D38: مشاكل ضخ الخامة | BJ38: =SUM(F38:BI38) -> 0 | BK38: =COUNT(F38:BI38) -> 0
B39: Machine failure | C39: MF11 | D39: تغيير خرطوم الهواء | BJ39: =SUM(F39:BI39) -> 0 | BK39: =COUNT(F39:BI39) -> 0
B40: Machine failure | C40: MF12 | D40: خلل فى سير الماكينة | BJ40: =SUM(F40:BI40) -> 0 | BK40: =COUNT(F40:BI40) -> 0
...

Sheet Techno
F1: =SUM(F5:F24) -> 0 | G1: =SUM(G5:G24) -> 0 | H1: =SUM(H5:H24) -> 0 | I1: =SUM(I5:I24) -> 0 | J1: =SUM(J5:J24) -> 0 | K1: =SUM(K5:K24) -> 0 | L1: =SUM(L5:L24) -> 0 | M1: =SUM(M5:M24) -> 0 | ... BJ1: =SUM(BJ5:BJ24) -> 9702
C2: Date | F2: 46082 | H2: 46083 | J2: 46084 | L2: 46085 | N2: 46086 | P2: 46087 | R2: 46088 | T2: 46089 | V2: 46090 | X2: 46091 | Z2: 46092 | AB2: 46093 | AD2: 46094 | AF2: 46095 | AH2: 46096 | AJ2: 46097 | AL2: 46098 | AN2: 46099 | AP2: 46100 | AR2: 46101 | AT2: 46102 | AV2: 46103 | AX2: 46104 | AZ2: 46105 | BB2: 46106 | BD2: 46107 | BF2: 46108 | BH2: 46109
C3: Shift | F3: sh1 | G3: sh2 | H3: sh1 | I3: sh2 | J3: sh1 | K3: sh2 | L3: sh1 | M3: sh2 | N3: sh1 | O3: sh2 | P3: sh1 | Q3: sh2 | R3: sh1 | S3: sh2 | T3: sh1 | U3: sh2 | V3: sh1 | W3: sh2 | X3: sh1 | Y3: sh2 | Z3: sh1 | AA3: sh2 | AB3: sh1 | AC3: sh2 | AD3: sh1 | AE3: sh2 | AF3: sh1 | AG3: sh2 | AH3: sh1 | AI3: sh2 | AJ3: sh1 | AK3: sh2 | AL3: sh1 | AM3: sh2 | AN3: sh1 | AO3: sh2 | AP3: sh1 | AQ3: sh2 | AR3: sh1 | AS3: sh2 | AT3: sh1 | AU3: sh2 | AV3: sh1 | AW3: sh2 | AX3: sh1 | AY3: sh2 | AZ3: sh1 | BA3: sh2 | BB3: sh1 | BC3: sh2 | BD3: sh1 | BE3: sh2 | BF3: sh1 | BG3: sh2 | BH3: sh1 | BI3: sh2
C4: Item code | D4: Item description | E4: Rate | F4: الاحد | H4: الاثنين | J4: الثلاثاء | L4: الاربعاء | N4: الخميس | P4: الجمعة | R4: السبت | T4: الاحد | V4: الاثنين | X4: الثلاثاء | Z4: الاربعاء | AB4: الخميس | AD4: الجمعة | AF4: السبت | AH4: الاحد | AJ4: الاثنين | AL4: الثلاثاء | AN4: الاربعاء | AP4: الخميس | AR4: الجمعة | AT4: السبت | AV4: الاحد | AX4: الاثنين | AZ4: الثلاثاء | BB4: الاربعاء | BD4: الخميس | BF4: الجمعة | BH4: السبت
C5: =VLOOKUP(D5,Products!B:D,2,FALSE) -> 41815002 | D5: كير اند مور كريم لليدين سيكرت تاتش 50مل | E5: 20 | Z5: 4000 | AB5: 3400 | AF5: 2302 | BJ5: =SUM(F5:BI5) -> 9702 | BK5: =COUNT(F5:BI5) -> 3
C6: =VLOOKUP(D6,Products!B:D,2,FALSE) -> #N/A | E6: 1 | BJ6: =SUM(F6:BI6) -> 0 | BK6: =COUNT(F6:BI6) -> 0
C7: =VLOOKUP(D7,Products!B:D,2,FALSE) -> #N/A | E7: 1 | BJ7: =SUM(F7:BI7) -> 0 | BK7: =COUNT(F7:BI7) -> 0
C8: =VLOOKUP(D8,Products!B:D,2,FALSE) -> #N/A | E8: 1 | BJ8: =SUM(F8:BI8) -> 0 | BK8: =COUNT(F8:BI8) -> 0
C9: =VLOOKUP(D9,Products!B:D,2,FALSE) -> #N/A | E9: 1 | BJ9: =SUM(F9:BI9) -> 0 | BK9: =COUNT(F9:BI9) -> 0
C10: =VLOOKUP(D10,Products!B:D,2,FALSE) -> #N/A | E10: 1 | BJ10: =SUM(F10:BI10) -> 0 | BK10: =COUNT(F10:BI10) -> 0
C11: =VLOOKUP(D11,Products!B:D,2,FALSE) -> #N/A | E11: 1 | BJ11: =SUM(F11:BI11) -> 0 | BK11: =COUNT(F11:BI11) -> 0
C12: =VLOOKUP(D12,Products!B:D,2,FALSE) -> #N/A | E12: 1 | BJ12: =SUM(F12:BI12) -> 0 | BK12: =COUNT(F12:BI12) -> 0
C13: =VLOOKUP(D13,Products!B:D,2,FALSE) -> #N/A | E13: 1 | BJ13: =SUM(F13:BI13) -> 0 | BK13: =COUNT(F13:BI13) -> 0
C14: =VLOOKUP(D14,Products!B:D,2,FALSE) -> #N/A | E14: 1 | BJ14: =SUM(F14:BI14) -> 0 | BK14: =COUNT(F14:BI14) -> 0
C15: =VLOOKUP(D15,Products!B:D,2,FALSE) -> #N/A | E15: 1 | BJ15: =SUM(F15:BI15) -> 0 | BK15: =COUNT(F15:BI15) -> 0
C16: =VLOOKUP(D16,Products!B:D,2,FALSE) -> #N/A | E16: 1 | BJ16: =SUM(F16:BI16) -> 0 | BK16: =COUNT(F16:BI16) -> 0
C17: =VLOOKUP(D17,Products!B:D,2,FALSE) -> #N/A | D17: `` | E17: 1 | BJ17: =SUM(F17:BI17) -> 0 | BK17: =COUNT(F17:BI17) -> 0
C18: =VLOOKUP(D18,Products!B:D,2,FALSE) -> #N/A | E18: 1 | BJ18: =SUM(F18:BI18) -> 0 | BK18: =COUNT(F18:BI18) -> 0
C19: =VLOOKUP(D19,Products!B:D,2,FALSE) -> #N/A | E19: 1 | BJ19: =SUM(F19:BI19) -> 0 | BK19: =COUNT(F19:BI19) -> 0
C20: =VLOOKUP(D20,Products!B:D,2,FALSE) -> #N/A | E20: 1 | BJ20: =SUM(F20:BI20) -> 0 | BK20: =COUNT(F20:BI20) -> 0
C21: =VLOOKUP(D21,Products!B:D,2,FALSE) -> #N/A | E21: 1 | BJ21: =SUM(F21:BI21) -> 0 | BK21: =COUNT(F21:BI21) -> 0
C22: =VLOOKUP(D22,Products!B:D,2,FALSE) -> #N/A | E22: 1 | BJ22: =SUM(F22:BI22) -> 0 | BK22: =COUNT(F22:BI22) -> 0
C23: =VLOOKUP(D23,Products!B:D,2,FALSE) -> #N/A | E23: 1 | BJ23: =SUM(F23:BI23) -> 0 | BK23: =COUNT(F23:BI23) -> 0
C24: =VLOOKUP(D24,Products!B:D,2,FALSE) -> #N/A | E24: 1 | BJ24: =SUM(F24:BI24) -> 0 | BK24: =COUNT(F24:BI24) -> 0
D25: التوالف | F25: =SUM(F26:F34) -> 0 | G25: =SUM(G26:G34) -> 0 | H25: =SUM(H26:H34) -> 0 | I25: =SUM(I26:I34) -> 0 | J25: =SUM(J26:J34) -> 0 | K25: =SUM(K26:K34) -> 0 | L25: =SUM(L26:L34) -> 0 | M25: =SUM(M26:M34) -> 0 | ... O25: =SUM(O26:O34) -> 0 | Q25: =SUM(Q26:Q34) -> 0 | R25: =SUM(R26:R34) -> 0 | S25: =SUM(S26:S34) -> 0 | T25: =SUM(T26:T34) -> 0 | U25: =SUM(U26:U34) -> 0 | V25: =SUM(V26:V34) -> 0 | W25: =SUM(W26:W34) -> 0 | X25: =SUM(X26:X34) -> 0 | ... BI25: =SUM(BI26:BI34) -> 0 | BJ25: =SUM(F25:BI25) -> 1150 | BK25: =COUNT(F25:BI25) -> 55
D26: (مورد) | BJ26: =SUM(F26:BI26) -> 0 | BK26: =COUNT(F26:BI26) -> 0
D27: عبوة | BJ27: =SUM(F27:BI27) -> 0 | BK27: =COUNT(F27:BI27) -> 0
D28: غطاء | BJ28: =SUM(F28:BI28) -> 0 | BK28: =COUNT(F28:BI28) -> 0
BJ29: =SUM(F29:BI29) -> 0 | BK29: =COUNT(F29:BI29) -> 0
D30: (تشغيل) | BJ30: =SUM(F30:BI30) -> 0 | BK30: =COUNT(F30:BI30) -> 0
D31: عبوة | Z31: 650 | AB31: 500 | BJ31: =SUM(F31:BI31) -> 1150 | BK31: =COUNT(F31:BI31) -> 2
D32: غطاء | BJ32: =SUM(F32:BI32) -> 0 | BK32: =COUNT(F32:BI32) -> 0
D33: بامب | BJ33: =SUM(F33:BI33) -> 0 | BK33: =COUNT(F33:BI33) -> 0
BJ34: =SUM(F34:BI34) -> 0 | BK34: =COUNT(F34:BI34) -> 0
D35: Unplanned downtime | F35: =SUM(F36:F113) -> 0 | G35: =SUM(G36:G113) -> 0 | H35: =SUM(H36:H113) -> 0 | I35: =SUM(I36:I113) -> 0 | J35: =SUM(J36:J113) -> 0 | K35: =SUM(K36:K113) -> 0 | L35: =SUM(L36:L113) -> 0 | M35: =SUM(M36:M113) -> 0 | ... O35: =SUM(O36:O113) -> 0 | Q35: =SUM(Q36:Q113) -> 0 | R35: =SUM(R36:R113) -> 0 | S35: =SUM(S36:S113) -> 0 | T35: =SUM(T36:T113) -> 0 | U35: =SUM(U36:U113) -> 0 | V35: =SUM(V36:V113) -> 0 | W35: =SUM(W36:W113) -> 0 | X35: =SUM(X36:X113) -> 0 | ... BI35: =SUM(BI36:BI113) -> 0 | BJ35: =SUM(F35:BI35) -> 335 | BK35: =COUNT(F35:BI35) -> 55
C36: =SUM(BJ37:BJ56) -> 335 | D36: اعطال الصيانة | BJ36: =SUM(F36:BI36) -> 0 | BK36: =COUNT(F36:BI36) -> 0
B37: Machine failure | C37: MF1 | D37: مشكلة فى النزل | BJ37: =SUM(F37:BI37) -> 0 | BK37: =COUNT(F37:BI37) -> 0
B38: Set up& adjustment | C38: ADJ1 | D38: ضبط الميزان | BJ38: =SUM(F38:BI38) -> 0 | BK38: =COUNT(F38:BI38) -> 0
B39: Machine failure | C39: MF2 | D39: مشكلة فى الميزان | BJ39: =SUM(F39:BI39) -> 0 | BK39: =COUNT(F39:BI39) -> 0
B40: Machine failure | C40: MF3 | D40: مشكلة فى المكبس | BJ40: =SUM(F40:BI40) -> 0 | BK40: =COUNT(F40:BI40) -> 0
...

Sheet Cream1
F1: =SUM(F5:F29) -> 9850 | G1: =SUM(G5:G29) -> 0 | H1: =SUM(H5:H29) -> 9601 | I1: =SUM(I5:I29) -> 0 | J1: =SUM(J5:J29) -> 4274 | K1: =SUM(K5:K29) -> 0 | L1: =SUM(L5:L29) -> 0 | M1: =SUM(M5:M29) -> 0 | ... BJ1: =SUM(BJ5:BJ29) -> 40813
C2: Date | F2: 46082 | H2: 46083 | J2: 46084 | L2: 46085 | N2: 46086 | P2: 46087 | R2: 46088 | T2: 46089 | V2: 46090 | X2: 46091 | Z2: 46092 | AB2: 46093 | AD2: 46094 | AF2: 46095 | AH2: 46096 | AJ2: 46097 | AL2: 46098 | AN2: 46099 | AP2: 46100 | AR2: 46101 | AT2: 46102 | AV2: 46103 | AX2: 46104 | AZ2: 46105 | BB2: 46106 | BD2: 46107 | BF2: 46108 | BH2: 46109
C3: Shift | F3: sh1 | G3: sh2 | H3: sh1 | I3: sh2 | J3: sh1 | K3: sh2 | L3: sh1 | M3: sh2 | N3: sh1 | O3: sh2 | P3: sh1 | Q3: sh2 | R3: sh1 | S3: sh2 | T3: sh1 | U3: sh2 | V3: sh1 | W3: sh2 | X3: sh1 | Y3: sh2 | Z3: sh1 | AA3: sh2 | AB3: sh1 | AC3: sh2 | AD3: sh1 | AE3: sh2 | AF3: sh1 | AG3: sh2 | AH3: sh1 | AI3: sh2 | AJ3: sh1 | AK3: sh2 | AL3: sh1 | AM3: sh2 | AN3: sh1 | AO3: sh2 | AP3: sh1 | AQ3: sh2 | AR3: sh1 | AS3: sh2 | AT3: sh1 | AU3: sh2 | AV3: sh1 | AW3: sh2 | AX3: sh1 | AY3: sh2 | AZ3: sh1 | BA3: sh2 | BB3: sh1 | BC3: sh2 | BD3: sh1 | BE3: sh2 | BF3: sh1 | BG3: sh2 | BH3: sh1 | BI3: sh2
C4: Item code | D4: Item description | E4: Rate | F4: الاحد | H4: الاثنين | J4: الثلاثاء | L4: الاربعاء | N4: الخميس | P4: الجمعة | R4: السبت | T4: الاحد | V4: الاثنين | X4: الثلاثاء | Z4: الاربعاء | AB4: الخميس | AD4: الجمعة | AF4: السبت | AH4: الاحد | AJ4: الاثنين | AL4: الثلاثاء | AN4: الاربعاء | AP4: الخميس | AR4: الجمعة | AT4: السبت | AV4: الاحد | AX4: الاثنين | AZ4: الثلاثاء | BB4: الاربعاء | BD4: الخميس | BF4: الجمعة | BH4: السبت
C5: =VLOOKUP(D5,Products!B:D,2,FALSE) -> 41870004 | D5: كير اند مور سوفت كريم جلسرين بشرة جافة 75مل | E5: 33 | F5: 9850 | H5: 3941 | BJ5: =SUM(F5:BI5) -> 13791 | BK5: =COUNT(F5:BI5) -> 2
C6: =VLOOKUP(D6,Products!B:D,2,FALSE) -> 41880004 | D6: كير اند مور سوفت كريم جلسرين و جوز هند 75مل | E6: 33 | H6: 5660 | J6: 4274 | N6: 2573 | T6: 2099 | BJ6: =SUM(F6:BI6) -> 14606 | BK6: =COUNT(F6:BI6) -> 4
C7: =VLOOKUP(D7,Products!B:D,2,FALSE) -> 40300002 | D7: GLYSOLID Cream - Alum-Tin 40gm | E7: 33 | V7: 7716 | X7: 4700 | BJ7: =SUM(F7:BI7) -> 12416 | BK7: =COUNT(F7:BI7) -> 2
C8: =VLOOKUP(D8,Products!B:D,2,FALSE) -> #N/A | E8: 1 | BJ8: =SUM(F8:BI8) -> 0 | BK8: =COUNT(F8:BI8) -> 0
C9: =VLOOKUP(D9,Products!B:D,2,FALSE) -> #N/A | E9: 1 | BJ9: =SUM(F9:BI9) -> 0 | BK9: =COUNT(F9:BI9) -> 0
C10: =VLOOKUP(D10,Products!B:D,2,FALSE) -> #N/A | E10: 1 | BJ10: =SUM(F10:BI10) -> 0 | BK10: =COUNT(F10:BI10) -> 0
C11: =VLOOKUP(D11,Products!B:D,2,FALSE) -> #N/A | E11: 1 | BJ11: =SUM(F11:BI11) -> 0 | BK11: =COUNT(F11:BI11) -> 0
C12: =VLOOKUP(D12,Products!B:D,2,FALSE) -> #N/A | E12: 1 | BJ12: =SUM(F12:BI12) -> 0 | BK12: =COUNT(F12:BI12) -> 0
C13: =VLOOKUP(D13,Products!B:D,2,FALSE) -> #N/A | E13: 1 | BJ13: =SUM(F13:BI13) -> 0 | BK13: =COUNT(F13:BI13) -> 0
C14: =VLOOKUP(D14,Products!B:D,2,FALSE) -> #N/A | E14: 1 | BJ14: =SUM(F14:BI14) -> 0 | BK14: =COUNT(F14:BI14) -> 0
C15: =VLOOKUP(D15,Products!B:D,2,FALSE) -> #N/A | E15: 1 | BJ15: =SUM(F15:BI15) -> 0 | BK15: =COUNT(F15:BI15) -> 0
C16: =VLOOKUP(D16,Products!B:D,2,FALSE) -> #N/A | E16: 1 | BJ16: =SUM(F16:BI16) -> 0 | BK16: =COUNT(F16:BI16) -> 0
C17: =VLOOKUP(D17,Products!B:D,2,FALSE) -> #N/A | E17: 1 | BJ17: =SUM(F17:BI17) -> 0 | BK17: =COUNT(F17:BI17) -> 0
C18: =VLOOKUP(D18,Products!B:D,2,FALSE) -> #N/A | E18: 1 | BJ18: =SUM(F18:BI18) -> 0 | BK18: =COUNT(F18:BI18) -> 0
C19: =VLOOKUP(D19,Products!B:D,2,FALSE) -> #N/A | E19: 1 | BJ19: =SUM(F19:BI19) -> 0 | BK19: =COUNT(F19:BI19) -> 0
... C21: =VLOOKUP(D21,Products!B:D,2,FALSE) -> #N/A | E21: 1 | BJ21: =SUM(F21:BI21) -> 0 | BK21: =COUNT(F21:BI21) -> 0
C22: =VLOOKUP(D22,Products!B:D,2,FALSE) -> #N/A | D22: `` | E22: 1 | BJ22: =SUM(F22:BI22) -> 0 | BK22: =COUNT(F22:BI22) -> 0
C23: =VLOOKUP(D23,Products!B:D,2,FALSE) -> #N/A | E23: 1 | BJ23: =SUM(F23:BI23) -> 0 | BK23: =COUNT(F23:BI23) -> 0
C24: =VLOOKUP(D24,Products!B:D,2,FALSE) -> #N/A | E24: 1 | BJ24: =SUM(F24:BI24) -> 0 | BK24: =COUNT(F24:BI24) -> 0
C25: =VLOOKUP(D25,Products!B:D,2,FALSE) -> #N/A | E25: 1 | BJ25: =SUM(F25:BI25) -> 0 | BK25: =COUNT(F25:BI25) -> 0
C26: =VLOOKUP(D26,Products!B:D,2,FALSE) -> #N/A | E26: 1 | BJ26: =SUM(F26:BI26) -> 0 | BK26: =COUNT(F26:BI26) -> 0
C27: =VLOOKUP(D27,Products!B:D,2,FALSE) -> #N/A | E27: 1 | BJ27: =SUM(F27:BI27) -> 0 | BK27: =COUNT(F27:BI27) -> 0
C28: =VLOOKUP(D28,Products!B:D,2,FALSE) -> #N/A | E28: 1 | BJ28: =SUM(F28:BI28) -> 0 | BK28: =COUNT(F28:BI28) -> 0
C29: =VLOOKUP(D29,Products!B:D,2,FALSE) -> #N/A | E29: 1 | BJ29: =SUM(F29:BI29) -> 0 | BK29: =COUNT(F29:BI29) -> 0
D30: التوالف | F30: =SUM(F31:F39) -> 140 | G30: =SUM(G31:G39) -> 0 | H30: =SUM(H31:H39) -> 149 | I30: =SUM(I31:I39) -> 0 | J30: =SUM(J31:J39) -> 111 | K30: =SUM(K31:K39) -> 0 | L30: =SUM(L31:L39) -> 0 | M30: =SUM(M31:M39) -> 0 | ... BI30: =SUM(BI31:BI39) -> 0 | BJ30: =SUM(F30:BI30) -> 427 | BK30: =COUNT(F30:BI30) -> 56
D31: (مورد) | BJ31: =SUM(F31:BI31) -> 0 | BK31: =COUNT(F31:BI31) -> 0
D32: عبوة | BJ32: =SUM(F32:BI32) -> 0 | BK32: =COUNT(F32:BI32) -> 0
D33: غطاء | BJ33: =SUM(F33:BI33) -> 0 | BK33: =COUNT(F33:BI33) -> 0
BJ34: =SUM(F34:BI34) -> 0 | BK34: =COUNT(F34:BI34) -> 0
D35: (تشغيل) | BJ35: =SUM(F35:BI35) -> 0 | BK35: =COUNT(F35:BI35) -> 0
D36: عبوة | F36: 90 | H36: 95 | J36: 39 | N36: 20 | BJ36: =SUM(F36:BI36) -> 244 | BK36: =COUNT(F36:BI36) -> 4
D37: غطاء | F37: 50 | H37: 54 | J37: 72 | N37: 7 | BJ37: =SUM(F37:BI37) -> 183 | BK37: =COUNT(F37:BI37) -> 4
D38: بامب | BJ38: =SUM(F38:BI38) -> 0 | BK38: =COUNT(F38:BI38) -> 0
BJ39: =SUM(F39:BI39) -> 0 | BK39: =COUNT(F39:BI39) -> 0
D40: Unplanned downtime | F40: =SUM(F41:F118) -> 0 | G40: =SUM(G41:G118) -> 0 | H40: =SUM(H41:H118) -> 45 | I40: =SUM(I41:I118) -> 0 | J40: =SUM(J41:J118) -> 0 | K40: =SUM(K41:K118) -> 0 | L40: =SUM(L41:L118) -> 0 | M40: =SUM(M41:M118) -> 0 | ... BI40: =SUM(BI41:BI118) -> 0 | BJ40: =SUM(F40:BI40) -> 75 | BK40: =COUNT(F40:BI40) -> 56
C41: =SUM(BJ42:BJ61) -> 0 | D41: اعطال الصيانة | BJ41: =SUM(F41:BI41) -> 0 | BK41: =COUNT(F41:BI41) -> 0
...

Sheet 4 NOZZOLE
F1: =SUM(F5:F19) -> 0 | G1: =SUM(G5:G19) -> 0 | H1: =SUM(H5:H19) -> 0 | I1: =SUM(I5:I19) -> 0 | J1: =SUM(J5:J19) -> 0 | K1: =SUM(K5:K19) -> 0 | L1: =SUM(L5:L19) -> 3972 | M1: =SUM(M5:M19) -> 0 | ... BJ1: =SUM(BJ5:BJ19) -> 11534
C2: Date | F2: 46082 | H2: 46083 | J2: 46084 | L2: 46085 | N2: 46086 | P2: 46087 | R2: 46088 | T2: 46089 | V2: 46090 | X2: 46091 | Z2: 46092 | AB2: 46093 | AD2: 46094 | AF2: 46095 | AH2: 46096 | AJ2: 46097 | AL2: 46098 | AN2: 46099 | AP2: 46100 | AR2: 46101 | AT2: 46102 | AV2: 46103 | AX2: 46104 | AZ2: 46105 | BB2: 46106 | BD2: 46107 | BF2: 46108 | BH2: 46109
C3: Shift | F3: sh1 | G3: sh2 | H3: sh1 | I3: sh2 | J3: sh1 | K3: sh2 | L3: sh1 | M3: sh2 | N3: sh1 | O3: sh2 | P3: sh1 | Q3: sh2 | R3: sh1 | S3: sh2 | T3: sh1 | U3: sh2 | V3: sh1 | W3: sh2 | X3: sh1 | Y3: sh2 | Z3: sh1 | AA3: sh2 | AB3: sh1 | AC3: sh2 | AD3: sh1 | AE3: sh2 | AF3: sh1 | AG3: sh2 | AH3: sh1 | AI3: sh2 | AJ3: sh1 | AK3: sh2 | AL3: sh1 | AM3: sh2 | AN3: sh1 | AO3: sh2 | AP3: sh1 | AQ3: sh2 | AR3: sh1 | AS3: sh2 | AT3: sh1 | AU3: sh2 | AV3: sh1 | AW3: sh2 | AX3: sh1 | AY3: sh2 | AZ3: sh1 | BA3: sh2 | BB3: sh1 | BC3: sh2 | BD3: sh1 | BE3: sh2 | BF3: sh1 | BG3: sh2 | BH3: sh1 | BI3: sh2
C4: Item code | D4: Item description | E4: Rate | F4: الاحد | H4: الاثنين | J4: الثلاثاء | L4: الاربعاء | N4: الخميس | P4: الجمعة | R4: السبت | T4: الاحد | V4: الاثنين | X4: الثلاثاء | Z4: الاربعاء | AB4: الخميس | AD4: الجمعة | AF4: السبت | AH4: الاحد | AJ4: الاثنين | AL4: الثلاثاء | AN4: الاربعاء | AP4: الخميس | AR4: الجمعة | AT4: السبت | AV4: الاحد | AX4: الاثنين | AZ4: الثلاثاء | BB4: الاربعاء | BD4: الخميس | BF4: الجمعة | BH4: السبت
C5: =VLOOKUP(D5,Products!B:D,2,FALSE) -> 40330013 | D5: GLYSOLID Lotion- Musk 500ml | E5: 20 | L5: 3972 | T5: 2185 | V5: 1600 | BJ5: =SUM(F5:BI5) -> 7757 | BK5: =COUNT(F5:BI5) -> 3
C6: 40330011 | D6: GLYSOLID Lotion- Classic 500ml | E6: 20 | N6: 1500 | BJ6: =SUM(F6:BI6) -> 1500 | BK6: =COUNT(F6:BI6) -> 1
C7: =VLOOKUP(D7,Products!B:D,2,FALSE) -> 40330001 | D7: GLYSOLID Lotion- Classic 200ml | E7: 20 | N7: 2277 | BJ7: =SUM(F7:BI7) -> 2277 | BK7: =COUNT(F7:BI7) -> 1
C8: =VLOOKUP(D8,Products!B:D,2,FALSE) -> #N/A | E8: 1 | BJ8: =SUM(F8:BI8) -> 0 | BK8: =COUNT(F8:BI8) -> 0
C9: =VLOOKUP(D9,Products!B:D,2,FALSE) -> #N/A | E9: 1 | BJ9: =SUM(F9:BI9) -> 0 | BK9: =COUNT(F9:BI9) -> 0
C10: =VLOOKUP(D10,Products!B:D,2,FALSE) -> #N/A | E10: 1 | BJ10: =SUM(F10:BI10) -> 0 | BK10: =COUNT(F10:BI10) -> 0
C11: =VLOOKUP(D11,Products!B:D,2,FALSE) -> #N/A | E11: 1 | BJ11: =SUM(F11:BI11) -> 0 | BK11: =COUNT(F11:BI11) -> 0
C12: =VLOOKUP(D12,Products!B:D,2,FALSE) -> #N/A | E12: 1 | BJ12: =SUM(F12:BI12) -> 0 | BK12: =COUNT(F12:BI12) -> 0
C13: =VLOOKUP(D13,Products!B:D,2,FALSE) -> #N/A | E13: 1 | BJ13: =SUM(F13:BI13) -> 0 | BK13: =COUNT(F13:BI13) -> 0
C14: =VLOOKUP(D14,Products!B:D,2,FALSE) -> #N/A | E14: 1 | BJ14: =SUM(F14:BI14) -> 0 | BK14: =COUNT(F14:BI14) -> 0
C15: =VLOOKUP(D15,Products!B:D,2,FALSE) -> #N/A | E15: 1 | BJ15: =SUM(F15:BI15) -> 0 | BK15: =COUNT(F15:BI15) -> 0
C16: =VLOOKUP(D16,Products!B:D,2,FALSE) -> #N/A | E16: 1 | BJ16: =SUM(F16:BI16) -> 0 | BK16: =COUNT(F16:BI16) -> 0
C17: =VLOOKUP(D17,Products!B:D,2,FALSE) -> #N/A | E17: 1 | BJ17: =SUM(F17:BI17) -> 0 | BK17: =COUNT(F17:BI17) -> 0
C18: =VLOOKUP(D18,Products!B:D,2,FALSE) -> #N/A | E18: 1 | BJ18: =SUM(F18:BI18) -> 0 | BK18: =COUNT(F18:BI18) -> 0
C19: =VLOOKUP(D19,Products!B:D,2,FALSE) -> #N/A | D19: `` | E19: 1 | BJ19: =SUM(F19:BI19) -> 0 | BK19: =COUNT(F19:BI19) -> 0
D20: التوالف | F20: =SUM(F21:F28) -> 0 | G20: =SUM(G21:G28) -> 0 | H20: =SUM(H21:H28) -> 0 | I20: =SUM(I21:I28) -> 0 | J20: =SUM(J21:J28) -> 0 | K20: =SUM(K21:K28) -> 0 | L20: =SUM(L21:L28) -> 0 | M20: =SUM(M21:M28) -> 0 | ... BI20: =SUM(BI21:BI28) -> 0 | BJ20: =SUM(F20:BI20) -> 94 | BK20: =COUNT(F20:BI20) -> 56
D21: (مورد) | BJ21: =SUM(F21:BI21) -> 0 | BK21: =COUNT(F21:BI21) -> 0
D22: عبوة | N22: 61 | BJ22: =SUM(F22:BI22) -> 61 | BK22: =COUNT(F22:BI22) -> 1
D23: غطاء | BJ23: =SUM(F23:BI23) -> 0 | BK23: =COUNT(F23:BI23) -> 0
BJ24: =SUM(F24:BI24) -> 0 | BK24: =COUNT(F24:BI24) -> 0
D25: (تشغيل) | BJ25: =SUM(F25:BI25) -> 0 | BK25: =COUNT(F25:BI25) -> 0
D26: عبوة | N26: 10 | T26: 6 | BJ26: =SUM(F26:BI26) -> 16 | BK26: =COUNT(F26:BI26) -> 2
D27: غطاء | BJ27: =SUM(F27:BI27) -> 0 | BK27: =COUNT(F27:BI27) -> 0
D28: بامب | N28: 5 | T28: 12 | BJ28: =SUM(F28:BI28) -> 17 | BK28: =COUNT(F28:BI28) -> 2
D29: Unplanned downtime | F29: =SUM(F30:F107) -> 0 | G29: =SUM(G30:G107) -> 0 | H29: =SUM(H30:H107) -> 0 | I29: =SUM(I30:I107) -> 0 | J29: =SUM(J30:J107) -> 0 | K29: =SUM(K30:K107) -> 0 | L29: =SUM(L30:L107) -> 101 | M29: =SUM(M30:M107) -> 0 | ... AW29: =SUM(AW30:AW107) -> 0 | AX29: 50 | AY29: =SUM(AY30:AY107) -> 0 | AZ29: =SUM(AZ30:AZ107) -> 0 | BA29: =SUM(BA30:BA107) -> 0 | BB29: =SUM(BB30:BB107) -> 0 | BC29: =SUM(BC30:BC107) -> 0 | BD29: =SUM(BD30:BD107) -> 0 | BE29: =SUM(BE30:BE107) -> 0 | BF29: =SUM(BF30:BF107) -> 0 | ... BI29: =SUM(BI30:BI107) -> 0 | BJ29: =SUM(F29:BI29) -> 191 | BK29: =COUNT(F29:BI29) -> 56
C30: =SUM(BJ31:BJ50) -> 50 | D30: اعطال الصيانة | BJ30: =SUM(F30:BI30) -> 0 | BK30: =COUNT(F30:BI30) -> 0
B31: Machine failure | C31: MF1 | D31: مشكلة فى النزل | L31: 35 | BJ31: =SUM(F31:BI31) -> 35 | BK31: =COUNT(F31:BI31) -> 1
B32: Set up& adjustment | C32: ADJ1 | D32: ضبط الميزان | BJ32: =SUM(F32:BI32) -> 0 | BK32: =COUNT(F32:BI32) -> 0
B33: Machine failure | C33: MF2 | D33: مشكلة فى الميزان | BJ33: =SUM(F33:BI33) -> 0 | BK33: =COUNT(F33:BI33) -> 0
B34: Machine failure | C34: MF3 | D34: مشكلة فى المكبس | BJ34: =SUM(F34:BI34) -> 0 | BK34: =COUNT(F34:BI34) -> 0
B35: Machine failure | C35: MF4 | D35: تسريب الخامة من العبوات | BJ35: =SUM(F35:BI35) -> 0 | BK35: =COUNT(F35:BI35) -> 0
B36: Machine failure | C36: MF5 | D36: مشكة فى ضغط العبوات (اللحام) | BJ36: =SUM(F36:BI36) -> 0 | BK36: =COUNT(F36:BI36) -> 0
B37: Machine failure | C37: MF6 | D37: مشكلة فى السخانات | BJ37: =SUM(F37:BI37) -> 0 | BK37: =COUNT(F37:BI37) -> 0
B38: Machine failure | C38: MF7 | D38: ضبط الكاميرا | BJ38: =SUM(F38:BI38) -> 0 | BK38: =COUNT(F38:BI38) -> 0
B39: Quality losses | C39: Q1 | D39: ضبط الكاميرا | BJ39: =SUM(F39:BI39) -> 0 | BK39: =COUNT(F39:BI39) -> 0
B40: utility loss | C40: UT1 | D40: مشكله في ضغط الهواء (فى الكومبرسور) | BJ40: =SUM(F40:BI40) -> 0 | BK40: =COUNT(F40:BI40) -> 0
...

Sheet OEE F1 march-2026
F1: =SUM(F5:F31) -> 0 | G1: =SUM(G5:G31) -> 0 | H1: =SUM(H5:H31) -> 0 | I1: =SUM(I5:I31) -> 0 | J1: =SUM(J5:J31) -> 3940 | K1: =SUM(K5:K31) -> 0 | L1: =SUM(L5:L31) -> 7079 | M1: =SUM(M5:M31) -> 0 | ... BJ1: =SUM(BJ5:BJ31) -> 61616
C2: Date | F2: 46082 | H2: 46083 | J2: 46084 | L2: 46085 | N2: 46086 | P2: 46087 | R2: 46088 | T2: 46089 | V2: 46090 | X2: 46091 | Z2: 46092 | AB2: 46093 | AD2: 46094 | AF2: 46095 | AH2: 46096 | AJ2: 46097 | AL2: 46098 | AN2: 46099 | AP2: 46100 | AR2: 46101 | AT2: 46102 | AV2: 46103 | AX2: 46104 | AZ2: 46105 | BB2: 46106 | BD2: 46107 | BF2: 46108 | BH2: 46109
C3: Shift | F3: sh1 | G3: sh2 | H3: sh1 | I3: sh2 | J3: sh1 | K3: sh2 | L3: sh1 | M3: sh2 | N3: sh1 | O3: sh2 | P3: sh1 | Q3: sh2 | R3: sh1 | S3: sh2 | T3: sh1 | U3: sh2 | V3: sh1 | W3: sh2 | X3: sh1 | Y3: sh2 | Z3: sh1 | AA3: sh2 | AB3: sh1 | AC3: sh2 | AD3: sh1 | AE3: sh2 | AF3: sh1 | AG3: sh2 | AH3: sh1 | AI3: sh2 | AJ3: sh1 | AK3: sh2 | AL3: sh1 | AM3: sh2 | AN3: sh1 | AO3: sh2 | AP3: sh1 | AQ3: sh2 | AR3: sh1 | AS3: sh2 | AT3: sh1 | AU3: sh2 | AV3: sh1 | AW3: sh2 | AX3: sh1 | AY3: sh2 | AZ3: sh1 | BA3: sh2 | BB3: sh1 | BC3: sh2 | BD3: sh1 | BE3: sh2 | BF3: sh1 | BG3: sh2 | BH3: sh1 | BI3: sh2
C4: Item code | D4: Item description | E4: Rate | F4: الاحد | H4: الاثنين | J4: الثلاثاء | L4: الاربعاء | N4: الخميس | P4: الجمعة | R4: السبت | T4: الاحد | V4: الاثنين | X4: الثلاثاء | Z4: الاربعاء | AB4: الخميس | AD4: الجمعة | AF4: السبت | AH4: الاحد | AJ4: الاثنين | AL4: الثلاثاء | AN4: الاربعاء | AP4: الخميس | AR4: الجمعة | AT4: السبت | AV4: الاحد | AX4: الاثنين | AZ4: الثلاثاء | BB4: الاربعاء | BD4: الخميس | BF4: الجمعة | BH4: السبت
C5: =VLOOKUP(D5,Products!B:D,2,FALSE) -> 40300026 | D5: جليسوليد كريم 125مل تصدير | E5: 22 | J5: 3940 | L5: 7079 | N5: 6850 | T5: 7200 | V5: =6164+43+8+297 -> 6512 | X5: 7100 | Z5: 7620 | AB5: 7515 | AF5: 7800 | BJ5: =SUM(F5:BI5) -> 61616 | BK5: =COUNT(F5:BI5) -> 9
C6: =VLOOKUP(D6,Products!B:D,2,FALSE) -> #N/A | E6: 1 | BJ6: =SUM(F6:BI6) -> 0 | BK6: =COUNT(F6:BI6) -> 0
C7: =VLOOKUP(D7,Products!B:D,2,FALSE) -> #N/A | E7: 1 | BJ7: =SUM(F7:BI7) -> 0 | BK7: =COUNT(F7:BI7) -> 0
C8: =VLOOKUP(D8,Products!B:D,2,FALSE) -> #N/A | E8: 1 | BJ8: =SUM(F8:BI8) -> 0 | BK8: =COUNT(F8:BI8) -> 0
C9: =VLOOKUP(D9,Products!B:D,2,FALSE) -> #N/A | E9: 1 | BJ9: =SUM(F9:BI9) -> 0 | BK9: =COUNT(F9:BI9) -> 0
C10: =VLOOKUP(D10,Products!B:D,2,FALSE) -> #N/A | E10: 1 | BJ10: =SUM(F10:BI10) -> 0 | BK10: =COUNT(F10:BI10) -> 0
C11: =VLOOKUP(D11,Products!B:D,2,FALSE) -> #N/A | E11: 1 | BJ11: =SUM(F11:BI11) -> 0 | BK11: =COUNT(F11:BI11) -> 0
C12: =VLOOKUP(D12,Products!B:D,2,FALSE) -> #N/A | E12: 1 | BJ12: =SUM(F12:BI12) -> 0 | BK12: =COUNT(F12:BI12) -> 0
C13: =VLOOKUP(D13,Products!B:D,2,FALSE) -> #N/A | E13: 1 | BJ13: =SUM(F13:BI13) -> 0 | BK13: =COUNT(F13:BI13) -> 0
C14: =VLOOKUP(D14,Products!B:D,2,FALSE) -> #N/A | E14: 1 | BJ14: =SUM(F14:BI14) -> 0 | BK14: =COUNT(F14:BI14) -> 0
C15: =VLOOKUP(D15,Products!B:D,2,FALSE) -> #N/A | E15: 1 | BJ15: =SUM(F15:BI15) -> 0 | BK15: =COUNT(F15:BI15) -> 0
C16: =VLOOKUP(D16,Products!B:D,2,FALSE) -> #N/A | E16: 1 | BJ16: =SUM(F16:BI16) -> 0 | BK16: =COUNT(F16:BI16) -> 0
C17: =VLOOKUP(D17,Products!B:D,2,FALSE) -> #N/A | E17: 1 | BJ17: =SUM(F17:BI17) -> 0 | BK17: =COUNT(F17:BI17) -> 0
... C22: =VLOOKUP(D22,Products!B:D,2,FALSE) -> #N/A | E22: 1 | BJ22: =SUM(F22:BI22) -> 0 | BK22: =COUNT(F22:BI22) -> 0
C23: =VLOOKUP(D23,Products!B:D,2,FALSE) -> #N/A | E23: 1 | P23: =SUM(P24:P31) -> 0 | Q23: =SUM(Q24:Q31) -> 0 | AD23: =SUM(AD24:AD31) -> 0 | AE23: =SUM(AE24:AE31) -> 0 | AR23: =SUM(AR24:AR31) -> 0 | AS23: =SUM(AS24:AS31) -> 0 | BF23: =SUM(BF24:BF31) -> 0 | BG23: =SUM(BG24:BG31) -> 0 | BJ23: =SUM(F23:BI23) -> 0 | BK23: =COUNT(F23:BI23) -> 8
C24: =VLOOKUP(D24,Products!B:D,2,FALSE) -> #N/A | D24: `` | E24: 1 | BJ24: =SUM(F24:BI24) -> 0 | BK24: =COUNT(F24:BI24) -> 0
C25: =VLOOKUP(D25,Products!B:D,2,FALSE) -> #N/A | E25: 1 | BJ25: =SUM(F25:BI25) -> 0 | BK25: =COUNT(F25:BI25) -> 0
C26: =VLOOKUP(D26,Products!B:D,2,FALSE) -> #N/A | E26: 1 | BJ26: =SUM(F26:BI26) -> 0 | BK26: =COUNT(F26:BI26) -> 0
C27: =VLOOKUP(D27,Products!B:D,2,FALSE) -> #N/A | E27: 1 | BJ27: =SUM(F27:BI27) -> 0 | BK27: =COUNT(F27:BI27) -> 0
C28: =VLOOKUP(D28,Products!B:D,2,FALSE) -> #N/A | E28: 1 | BJ28: =SUM(F28:BI28) -> 0 | BK28: =COUNT(F28:BI28) -> 0
C29: =VLOOKUP(D29,Products!B:D,2,FALSE) -> #N/A | E29: 1 | BJ29: =SUM(F29:BI29) -> 0 | BK29: =COUNT(F29:BI29) -> 0
C30: =VLOOKUP(D30,Products!B:D,2,FALSE) -> #N/A | E30: 1 | BJ30: =SUM(F30:BI30) -> 0 | BK30: =COUNT(F30:BI30) -> 0
C31: =VLOOKUP(D31,Products!B:D,2,FALSE) -> #N/A | E31: 1 | BJ31: =SUM(F31:BI31) -> 0 | BK31: =COUNT(F31:BI31) -> 0
D32: التوالف | F32: =SUM(F33:F41) -> 0 | G32: =SUM(G33:G41) -> 0 | H32: =SUM(H33:H41) -> 0 | I32: =SUM(I33:I41) -> 0 | J32: =SUM(J33:J41) -> 79 | K32: =SUM(K33:K41) -> 0 | L32: =SUM(L33:L41) -> 246 | M32: =SUM(M33:M41) -> 0 | ... O32: =SUM(O33:O41) -> 0 | P32: =SUM(P33:P110) -> 0 | Q32: =SUM(Q33:Q110) -> 0 | R32: =SUM(R33:R41) -> 0 | S32: =SUM(S33:S41) -> 0 | T32: =SUM(T33:T41) -> 60 | U32: =SUM(U33:U41) -> 0 | V32: =SUM(V33:V41) -> 0 | W32: =SUM(W33:W41) -> 0 | X32: =SUM(X33:X41) -> 135 | Y32: =SUM(Y33:Y41) -> 0 | ... AC32: =SUM(AC33:AC41) -> 0 | AD32: =SUM(AD33:AD110) -> 0 | AE32: =SUM(AE33:AE110) -> 0 | AF32: =SUM(AF33:AF41) -> 0 | AG32: =SUM(AG33:AG41) -> 0 | AH32: =SUM(AH33:AH41) -> 0 | AI32: =SUM(AI33:AI41) -> 0 | AJ32: =SUM(AJ33:AJ41) -> 0 | AK32: =SUM(AK33:AK41) -> 0 | AL32: =SUM(AL33:AL41) -> 0 | AM32: =SUM(AM33:AM41) -> 0 | ... AQ32: =SUM(AQ33:AQ41) -> 0 | AR32: =SUM(AR33:AR110) -> 0 | AS32: =SUM(AS33:AS110) -> 0 | AT32: =SUM(AT33:AT41) -> 0 | AU32: =SUM(AU33:AU41) -> 0 | AV32: =SUM(AV33:AV41) -> 0 | AW32: =SUM(AW33:AW41) -> 0 | AX32: =SUM(AX33:AX41) -> 0 | AY32: =SUM(AY33:AY41) -> 0 | AZ32: =SUM(AZ33:AZ41) -> 0 | BA32: =SUM(BA33:BA41) -> 0 | ... BE32: =SUM(BE33:BE41) -> 0 | BF32: =SUM(BF33:BF110) -> 0 | BG32: =SUM(BG33:BG110) -> 0 | BH32: =SUM(BH33:BH41) -> 0 | BI32: =SUM(BI33:BI41) -> 0 | BJ32: =SUM(F32:BI32) -> 687 | BK32: =COUNT(F32:BI32) -> 56
D33: (مورد) | BJ33: =SUM(F33:BI33) -> 0 | BK33: =COUNT(F33:BI33) -> 0
D34: عبوة | X34: 60 | BJ34: =SUM(F34:BI34) -> 60 | BK34: =COUNT(F34:BI34) -> 1
D35: غطاء | BJ35: =SUM(F35:BI35) -> 0 | BK35: =COUNT(F35:BI35) -> 0
BJ36: =SUM(F36:BI36) -> 0 | BK36: =COUNT(F36:BI36) -> 0
D37: (تشغيل) | BJ37: =SUM(F37:BI37) -> 0 | BK37: =COUNT(F37:BI37) -> 0
D38: عبوة | L38: 113 | N38: 50 | T38: 50 | X38: 52 | BJ38: =SUM(F38:BI38) -> 265 | BK38: =COUNT(F38:BI38) -> 4
D39: غطاء | J39: 79 | L39: 133 | N39: 117 | T39: 10 | X39: 23 | BJ39: =SUM(F39:BI39) -> 362 | BK39: =COUNT(F39:BI39) -> 5
D40: بامب | BJ40: =SUM(F40:BI40) -> 0 | BK40: =COUNT(F40:BI40) -> 0
BJ41: =SUM(F41:BI41) -> 0 | BK41: =COUNT(F41:BI41) -> 0
D42: Unplanned downtime | F42: =SUM(F43:F120) -> 0 | G42: =SUM(G43:G120) -> 0 | H42: =SUM(H43:H120) -> 0 | I42: =SUM(I43:I120) -> 0 | J42: =SUM(J43:J120) -> 0 | K42: =SUM(K43:K120) -> 0 | L42: =SUM(L43:L120) -> 0 | M42: =SUM(M43:M120) -> 0 | ... O42: =SUM(O43:O120) -> 0 | R42: =SUM(R43:R120) -> 0 | S42: =SUM(S43:S120) -> 0 | T42: =SUM(T43:T120) -> 0 | U42: =SUM(U43:U120) -> 0 | V42: =SUM(V43:V120) -> 31 | W42: =SUM(W43:W120) -> 0 | X42: =SUM(X43:X120) -> 0 | Y42: =SUM(Y43:Y120) -> 0 | ... AC42: =SUM(AC43:AC120) -> 0 | AF42: =SUM(AF43:AF120) -> 0 | AG42: =SUM(AG43:AG120) -> 0 | AH42: =SUM(AH43:AH120) -> 0 | AI42: =SUM(AI43:AI120) -> 0 | AJ42: =SUM(AJ43:AJ120) -> 0 | AK42: =SUM(AK43:AK120) -> 0 | AL42: =SUM(AL43:AL120) -> 0 | AM42: =SUM(AM43:AM120) -> 0 | ... AQ42: =SUM(AQ43:AQ120) -> 0 | AT42: =SUM(AT43:AT120) -> 0 | AU42: =SUM(AU43:AU120) -> 0 | AV42: =SUM(AV43:AV120) -> 0 | AW42: =SUM(AW43:AW120) -> 0 | AX42: =SUM(AX43:AX120) -> 0 | AY42: =SUM(AY43:AY120) -> 0 | AZ42: =SUM(AZ43:AZ120) -> 0 | BA42: =SUM(BA43:BA120) -> 0 | ... BE42: =SUM(BE43:BE120) -> 0 | BH42: =SUM(BH43:BH120) -> 0 | BI42: =SUM(BI43:BI120) -> 0 | BJ42: =SUM(F42:BI42) -> 31 | BK42: =COUNT(F42:BI42) -> 48
C43: =SUM(BJ44:BJ63) -> 0 | D43: اعطال الصيانة | BJ43: =SUM(F43:BI43) -> 0 | BK43: =COUNT(F43:BI43) -> 0
B44: Machine failure | C44: MF1 | D44: مشكلة فى النزل | BJ44: =SUM(F44:BI44) -> 0 | BK44: =COUNT(F44:BI44) -> 0
...

Sheet 6 Nozzole 
F1: =SUM(F5:F19) -> 1556 | G1: =SUM(G5:G19) -> 0 | H1: =SUM(H5:H19) -> 2711 | I1: =SUM(I5:I19) -> 0 | J1: =SUM(J5:J19) -> 4068 | K1: =SUM(K5:K19) -> 0 | L1: =SUM(L5:L19) -> 4733 | M1: =SUM(M5:M19) -> 0 | ... BJ1: =SUM(BJ5:BJ19) -> 15378
C2: Date | F2: 46082 | H2: 46083 | J2: 46084 | L2: 46085 | N2: 46086 | P2: 46087 | R2: 46088 | T2: 46089 | V2: 46090 | X2: 46091 | Z2: 46092 | AB2: 46093 | AD2: 46094 | AF2: 46095 | AH2: 46096 | AJ2: 46097 | AL2: 46098 | AN2: 46099 | AP2: 46100 | AR2: 46101 | AT2: 46102 | AV2: 46103 | AX2: 46104 | AZ2: 46105 | BB2: 46106 | BD2: 46107 | BF2: 46108 | BH2: 46109
C3: Shift | F3: sh1 | G3: sh2 | H3: sh1 | I3: sh2 | J3: sh1 | K3: sh2 | L3: sh1 | M3: sh2 | N3: sh1 | O3: sh2 | P3: sh1 | Q3: sh2 | R3: sh1 | S3: sh2 | T3: sh1 | U3: sh2 | V3: sh1 | W3: sh2 | X3: sh1 | Y3: sh2 | Z3: sh1 | AA3: sh2 | AB3: sh1 | AC3: sh2 | AD3: sh1 | AE3: sh2 | AF3: sh1 | AG3: sh2 | AH3: sh1 | AI3: sh2 | AJ3: sh1 | AK3: sh2 | AL3: sh1 | AM3: sh2 | AN3: sh1 | AO3: sh2 | AP3: sh1 | AQ3: sh2 | AR3: sh1 | AS3: sh2 | AT3: sh1 | AU3: sh2 | AV3: sh1 | AW3: sh2 | AX3: sh1 | AY3: sh2 | AZ3: sh1 | BA3: sh2 | BB3: sh1 | BC3: sh2 | BD3: sh1 | BE3: sh2 | BF3: sh1 | BG3: sh2 | BH3: sh1 | BI3: sh2
C4: Item code | D4: Item description | E4: Rate | F4: الاحد | H4: الاثنين | J4: الثلاثاء | L4: الاربعاء | N4: الخميس | P4: الجمعة | R4: السبت | T4: الاحد | V4: الاثنين | X4: الثلاثاء | Z4: الاربعاء | AB4: الخميس | AD4: الجمعة | AF4: السبت | AH4: الاحد | AJ4: الاثنين | AL4: الثلاثاء | AN4: الاربعاء | AP4: الخميس | AR4: الجمعة | AT4: السبت | AV4: الاحد | AX4: الاثنين | AZ4: الثلاثاء | BB4: الاربعاء | BD4: الخميس | BF4: الجمعة | BH4: السبت
C5: =VLOOKUP(D5,Products!B:D,2,FALSE) -> 430000003 | D5: تريو برو هاند سوب باليمون الاخضر 500 مل | E5: 20 | F5: 1556 | H5: 1181 | BJ5: =SUM(F5:BI5) -> 2737 | BK5: =COUNT(F5:BI5) -> 2
C6: =VLOOKUP(D6,Products!B:D,2,FALSE) -> 430000002 | D6: تريو برو هاند سوب برائحة العود الملكى 500مل | E6: 20 | H6: 1530 | J6: =1478+1702 -> 3180 | BJ6: =SUM(F6:BI6) -> 4710 | BK6: =COUNT(F6:BI6) -> 2
C7: =VLOOKUP(D7,Products!B:D,2,FALSE) -> 45700023 | D7: فومز هاند سوب برائحة الليمون بالنعناع 500 مل | E7: 20 | J7: 888 | BJ7: =SUM(F7:BI7) -> 888 | BK7: =COUNT(F7:BI7) -> 1
C8: =VLOOKUP(D8,Products!B:D,2,FALSE) -> 43010001 | D8: تريو برو شاور چيل برائحة الزهور البيضاء 800مل | E8: 20 | L8: =2503+2230 -> 4733 | N8: 470 | BJ8: =SUM(F8:BI8) -> 5203 | BK8: =COUNT(F8:BI8) -> 2
C9: =VLOOKUP(D9,Products!B:D,2,FALSE) -> 43010003 | D9: تريو برو شاور چيل برائحة الكيوى 800مل | E9: 20 | N9: 1840 | BJ9: =SUM(F9:BI9) -> 1840 | BK9: =COUNT(F9:BI9) -> 1
C10: =VLOOKUP(D10,Products!B:D,2,FALSE) -> 43020002 | D10: تريو برو شامبو خالى من السلفات بخليط الزيوت 500مل | E10: 20 | T10: 2100
C11: =VLOOKUP(D11,Products!B:D,2,FALSE) -> 430000001 | D11: تريو برو هاند سوب برائحة الزهور البيضاء 500مل | E11: 20 | V11: 2460
C12: =VLOOKUP(D12,Products!B:D,2,FALSE) -> 45700021 | D12: Foaz hand wash Lavender& violets 500ml | E12: 20 | Z12: 1274 | AB12: 710
C13: =VLOOKUP(D13,Products!B:D,2,FALSE) -> #N/A | E13: 1
C14: =VLOOKUP(D14,Products!B:D,2,FALSE) -> #N/A | E14: 1
C15: =VLOOKUP(D15,Products!B:D,2,FALSE) -> #N/A | E15: 1
C16: =VLOOKUP(D16,Products!B:D,2,FALSE) -> #N/A | E16: 1
C17: =VLOOKUP(D17,Products!B:D,2,FALSE) -> #N/A | E17: 1
C18: =VLOOKUP(D18,Products!B:D,2,FALSE) -> #N/A | E18: 1
C19: =VLOOKUP(D19,Products!B:D,2,FALSE) -> #N/A | E19: 1 | BJ19: =SUM(F19:BI19) -> 0 | BK19: =COUNT(F19:BI19) -> 0
D20: التوالف | F20: =SUM(F21:F28) -> 0 | G20: =SUM(G21:G28) -> 0 | H20: =SUM(H21:H28) -> 0 | I20: =SUM(I21:I28) -> 0 | J20: =SUM(J21:J28) -> 0 | K20: =SUM(K21:K28) -> 0 | L20: =SUM(L21:L28) -> 0 | M20: =SUM(M21:M28) -> 0 | ... BI20: =SUM(BI21:BI28) -> 0 | BJ20: =SUM(F20:BI20) -> 0 | BK20: =COUNT(F20:BI20) -> 56
D21: (مورد) | BJ21: =SUM(F21:BI21) -> 0 | BK21: =COUNT(F21:BI21) -> 0
D22: عبوة | BJ22: =SUM(F22:BI22) -> 0 | BK22: =COUNT(F22:BI22) -> 0
D23: غطاء | BJ23: =SUM(F23:BI23) -> 0 | BK23: =COUNT(F23:BI23) -> 0
BJ24: =SUM(F24:BI24) -> 0 | BK24: =COUNT(F24:BI24) -> 0
D25: (تشغيل) | BJ25: =SUM(F25:BI25) -> 0 | BK25: =COUNT(F25:BI25) -> 0
D26: عبوة | BJ26: =SUM(F26:BI26) -> 0 | BK26: =COUNT(F26:BI26) -> 0
D27: غطاء | BJ27: =SUM(F27:BI27) -> 0 | BK27: =COUNT(F27:BI27) -> 0
D28: بامب | BJ28: =SUM(F28:BI28) -> 0 | BK28: =COUNT(F28:BI28) -> 0
D29: Unplanned downtime | F29: =SUM(F30:F107) -> 0 | G29: =SUM(G30:G107) -> 0 | H29: =SUM(H30:H107) -> 20 | I29: =SUM(I30:I107) -> 0 | J29: =SUM(J30:J107) -> 64 | K29: =SUM(K30:K107) -> 0 | L29: =SUM(L30:L107) -> 85 | M29: =SUM(M30:M107) -> 0 | ... BI29: =SUM(BI30:BI107) -> 0 | BJ29: =SUM(F29:BI29) -> 209 | BK29: =COUNT(F29:BI29) -> 56
